<?xml version='1.0'?>
<gazebo version='1.2'>
<model name="trikey_assembly">
<static>false</static>
<!--LINKS-->
<link name="base">
  <pose>0.0 0.0 0.23 1.5707 0 0</pose>
  <self_collide>false</self_collide>
  
  <visual name="base_visual">
    <geometry> 
      <!--box><size>0.4 0.2 0.6</size></box-->     
      <mesh>
		<uri>model://Trikey_Assembly/Meshes/Trikey_assembly_Gwen_noWheels2_coarse.STL</uri>		
      </mesh>
    </geometry>
  </visual>
    
  <inertial> 
	<mass>32.7</mass>
  	<pose>-0.003048 0.18415 -0.00254 0.0 0.0 0.0</pose>  	
  	<inertia> 
  		<ixx>1.747</ixx>  		
  		<iyy>1.192</iyy>  		
  		<izz>1.747</izz>
  	</inertia>
  </inertial>
  
  <collision name="base_collision_cyl">
    <pose>0.0 0.2 0.0 1.5707 0 0</pose>
	<geometry>
	<cylinder>
		<length>0.65</length>
		<radius>0.27</radius>
	</cylinder>
	</geometry>		
  </collision>echo
</link>

<link name="omni_wheel_0">
  <pose>-0.0 -0.293 0.1 1.5707 0 0</pose>
  <self_collide>false</self_collide>
  <visual name="omni_wheel_0_visual">
    <geometry>
      <!--cylinder>
	     <length>0.025</length>
	     <radius>0.101</radius>
     </cylinder-->
      <mesh><uri>model://Trikey_Assembly/Meshes/wheel_set_assembly2_coarse.STL</uri></mesh>
    </geometry>
  </visual>
  
  <inertial> 
	<mass>0.66625</mass>
  	<pose>-0.0001 -0.0002 -.05808 0.0 0.0 0.0</pose>  	
  	<inertia>
  		<ixx>0.001603175</ixx>
  		<ixy>0.000004598</ixy>
  		<ixz>0.000015199</ixz>
  		<iyy>0.001603387</iyy>
  		<iyz>0.000041656</iyz>
  		<izz>0.002798144</izz>
  	</inertia>
  </inertial>
  
  <collision name="omni_collision_cyl">
     <pose>0.0 0.0 -0.05 0.0 0 0</pose>
     <geometry>
     <cylinder>
	     <length>0.025</length>
	     <radius>0.101</radius>
     </cylinder>
     </geometry>
     
     <!--surface>
        <bounce>
        	<restitution_coefficient>0.1</restitution_coefficient>
        	<threshold>0.005</threshold>
        </bounce>
        <friction>
     	<ode>
     		<mu>0.01</mu>
     		<mu2>0.8</mu2>
     		<fdir1>0 0 1</fdir1>     		
     	</ode>
     	</friction>
     </surface-->
  </collision>      
</link>

<link name="omni_wheel_1">
  <pose>0.25375 0.1465 0.1 1.5707 0.0 2.0844</pose>
  <self_collide>false</self_collide>
  <visual name="omni_wheel_1_visual">
    <geometry>
      <!--cylinder>
	     <length>0.025</length>
	     <radius>0.101</radius>
     </cylinder-->
      <mesh><uri>model://Trikey_Assembly/Meshes/wheel_set_assembly2_coarse.STL</uri></mesh>
    </geometry>
  </visual>
  
  <inertial> 
	<mass>0.66625</mass>
  	<pose>-0.0001 -0.0002 -.05808 0.0 0.0 0.0</pose>  	
  	<inertia>
  		<ixx>0.001603175</ixx>
  		<ixy>0.000004598</ixy>
  		<ixz>0.000015199</ixz>
  		<iyy>0.001603387</iyy>
  		<iyz>0.000041656</iyz>
  		<izz>0.002798144</izz>
  	</inertia>
  </inertial>
  
  <collision name="omni_collision_cyl">
     <pose>0.0 0.0 -0.05 0.0 0 0</pose>
     <geometry>
     <cylinder>
	     <length>0.025</length>
	     <radius>0.101</radius>
	 </cylinder>
     </geometry>
     
     <surface>
        <bounce>
        	<restitution_coefficient>0.1</restitution_coefficient>
        	<threshold>0.005</threshold>
        </bounce>
        <!--friction>
     	<ode>
     		<mu>0.01</mu>
     		<mu2>0.8</mu2>
     		<fdir1>0 0 1</fdir1>     		
     	</ode>
     	</friction-->
     </surface>
  </collision>  
</link>

<link name="omni_wheel_2">
  <self_collide>false</self_collide>
  <pose>-0.25375 0.14650 0.1 1.5708 -0.0 -2.0944</pose>
  <visual name="omni_wheel_2_visual">
    <geometry>
     <!--cylinder>
	     <length>0.025</length>
	     <radius>0.101</radius>
     </cylinder-->
      <mesh><uri>model://Trikey_Assembly/Meshes/wheel_set_assembly2_coarse.STL</uri></mesh>
    </geometry>
  </visual>
  
  <inertial> 
	<mass>0.66625</mass>
  	<pose>-0.0001 -0.0002 -.05808 0.0 0.0 0.0</pose>  	
  	<inertia>
  		<ixx>0.001603175</ixx>
  		<ixy>0.000004598</ixy>
  		<ixz>0.000015199</ixz>
  		<iyy>0.001603387</iyy>
  		<iyz>0.000041656</iyz>
  		<izz>0.002798144</izz>
  	</inertia>
  </inertial>
  
  <collision name="omni_collision_cyl">
     <pose>0.0 0.0 -0.05 0.0 0 0</pose>
     <geometry>
     <cylinder>
	     <length>0.025</length>
	     <radius>0.101</radius>
     </cylinder>
     </geometry>
     
     <!--surface>
        <bounce>
        	<restitution_coefficient>0.1</restitution_coefficient>
        	<threshold>0.005</threshold>
        </bounce>
        <friction>
     	<ode>
     		<mu>0.01</mu>
     		<mu2>0.8</mu2>
     		<fdir1>0 0 1</fdir1>     		
     	</ode>
     	</friction>
     </surface-->
  </collision>  
</link>

<!--Joints-->

<joint type="revolute" name="base_to_wheel_0">
  <pose>0.0 0.0 -0.05 0.0 0 0</pose>
  <child>omni_wheel_0</child>
  <parent>base</parent>
  <axis>
    <xyz>0 0 1</xyz>
    <dynamics> <!--RESET BETTER PHYSICAL-->
    	<damping>0.1</damping>
    	<friction>0.1</friction>
    </dynamics>
  </axis>
</joint>

<joint type="revolute" name="base_to_wheel_1">
  <pose>0.0 0.0 -0.05 0.0 0 0</pose>
  <child>omni_wheel_1</child>
  <parent>base</parent>
  <axis>
    <xyz>0 0 1</xyz>
    <dynamics> <!--RESET BETTER PHYSICAL-->
    	<damping>0.1</damping>
    	<friction>0.1</friction>
    </dynamics>
  </axis>
</joint>

<joint type="revolute" name="base_to_wheel_2">
  <pose>0.0 0.0 -0.05 0.0 0 0</pose>
  <child>omni_wheel_2</child>
  <parent>base</parent>
  <axis>
    <xyz>0 0 1</xyz>
    <dynamics> <!--RESET BETTER PHYSICAL-->
    	<damping>0.1</damping>
    	<friction>0.1</friction>
    </dynamics>
  </axis>
</joint>

</model>
</gazebo>
