<?xml version="1.0" ?>

<robot name="atlas_legs_plain">

    <macro name="atlas_legs_plain">
        <link name="l_foot">
            <inertial>
                <mass value="2.05" />
                <origin xyz="0.027 0 -0.067" rpy="0 -0 0" />
                <inertia ixx="0.002" ixy="0" ixz="0" iyy="0.007" iyz="0" izz="0.008" />
            </inertial>
            <visual>
                <origin xyz="0 0 0" rpy="0 -0 0" />
                <geometry>
                    <mesh filename="${modelPath}/meshes_v3/l_foot.dae" scale="1 1 1" />
                </geometry>
            </visual>
            <!--
            <collision>
                <origin xyz="0 0 0" rpy="0 -0 0" />
                <geometry>
                    <mesh filename="${modelPath}/meshes_v3/l_foot.stl" scale="1 1 1" />
                </geometry>
            </collision>
            -->
            <collision>
              <origin rpy="0 0 0 " xyz="0.049 0 -0.053"/>
              <geometry name="l_foot">
                <box size="0.27 0.1301 0.056"/>
              </geometry>
            </collision>
        </link>
        <link name="l_lglut">
            <inertial>
                <mass value="0.866" />
                <origin xyz="0.0133341 0.0170484 -0.0312052" rpy="0 -0 0" />
                <inertia ixx="0.000691326" ixy="-2.24344e-05" ixz="2.50508e-06" iyy="0.00126856" iyz="0.000137862" izz="0.00106487" />
            </inertial>
            <visual>
                <origin xyz="0 0 0" rpy="0 -0 0" />
                <geometry>
                    <mesh filename="${modelPath}/meshes_v3/l_lglut.dae" scale="1 1 1" />
                </geometry>
            </visual>
            <collision>
                <origin xyz="0 0 0" rpy="0 -0 0" />
                <geometry>
                    <mesh filename="${modelPath}/meshes_v3/l_lglut.stl" scale="1 1 1" />
                </geometry>
            </collision>
        </link>
        <link name="l_lleg">
            <inertial>
                <mass value="5.479" />
                <origin xyz="0.001 0 -0.187" rpy="0 -0 0" />
                <inertia ixx="0.077" ixy="0" ixz="-0.003" iyy="0.076" iyz="0" izz="0.01" />
            </inertial>
            <visual>
                <origin xyz="0 0 0" rpy="0 -0 0" />
                <geometry>
                    <mesh filename="${modelPath}/meshes_v3/l_lleg.dae" scale="1 1 1" />
                </geometry>
            </visual>
            <collision>
                <origin xyz="0 0 0" rpy="0 -0 0" />
                <geometry>
                    <mesh filename="${modelPath}/meshes_v3/l_lleg.stl" scale="1 1 1" />
                </geometry>
            </collision>
        </link>
        <link name="l_talus">
            <inertial>
                <mass value="0.125" />
                <origin xyz="0 0 0" rpy="0 -0 0" />
                <inertia ixx="1.01674e-05" ixy="0" ixz="0" iyy="8.42775e-06" iyz="0" izz="1.30101e-05" />
            </inertial>
            <visual>
                <origin xyz="0 0 0" rpy="0 -0 0" />
                <geometry>
                    <mesh filename="${modelPath}/meshes_v3/l_talus.dae" scale="1 1 1" />
                </geometry>
            </visual>
            <collision>
                <origin xyz="0 0 0" rpy="0 -0 0" />
                <geometry>
                    <mesh filename="${modelPath}/meshes_v3/l_talus.stl" scale="1 1 1" />
                </geometry>
            </collision>
        </link>
        <link name="l_uglut">
            <inertial>
                <mass value="0.648" />
                <origin xyz="0.00529262 -0.00344732 0.00313046" rpy="0 -0 0" />
                <inertia ixx="0.00074276" ixy="-3.79607e-08" ixz="-2.79549e-05" iyy="0.000688179" iyz="-3.2735e-08" izz="0.00041242" />
            </inertial>
            <visual>
                <origin xyz="0 0 0" rpy="0 -0 0" />
                <geometry>
                    <mesh filename="${modelPath}/meshes_v3/l_uglut.dae" scale="1 1 1" />
                </geometry>
            </visual>
            <collision>
                <origin xyz="0 0 0" rpy="0 -0 0" />
                <geometry>
                    <mesh filename="${modelPath}/meshes_v3/l_uglut.stl" scale="1 1 1" />
                </geometry>
            </collision>
        </link>
        <link name="l_uleg">
            <inertial>
                <mass value="9.209" />
                <origin xyz="0 0 -0.21" rpy="0 -0 0" />
                <inertia ixx="0.09" ixy="0" ixz="0" iyy="0.09" iyz="0" izz="0.02" />
            </inertial>
            <visual>
                <origin xyz="0 0 0" rpy="0 -0 0" />
                <geometry>
                    <mesh filename="${modelPath}/meshes_v3/l_uleg.dae" scale="1 1 1" />
                </geometry>
            </visual>
            <collision>
                <origin xyz="0 0 0" rpy="0 -0 0" />
                <geometry>
                    <mesh filename="${modelPath}/meshes_v3/l_uleg.stl" scale="1 1 1" />
                </geometry>
            </collision>
        </link>
        <link name="pelvis">
            <inertial>
                <mass value="17.882" />
                <origin xyz="0.0111 0 0.0271" rpy="0 -0 0" />
                <inertia ixx="0.1244" ixy="0.0008" ixz="-0.0007" iyy="0.0958" iyz="-0.0005" izz="0.1167" />
            </inertial>
            <visual>
                <origin xyz="0 0 0" rpy="0 -0 0" />
                <geometry>
                    <mesh filename="${modelPath}/meshes_v3/pelvis.dae" scale="1 1 1" />
                </geometry>
            </visual>
            <collision>
                <origin xyz="0 0 0" rpy="0 -0 0" />
                <geometry>
                    <mesh filename="${modelPath}/meshes_v3/pelvis.stl" scale="1 1 1" />
                </geometry>
            </collision>
        </link>
        <link name="r_foot">
            <inertial>
                <mass value="2.05" />
                <origin xyz="0.027 0 -0.067" rpy="0 -0 0" />
                <inertia ixx="0.002" ixy="0" ixz="0" iyy="0.007" iyz="0" izz="0.008" />
            </inertial>
            <visual>
                <origin xyz="0 0 0" rpy="0 -0 0" />
                <geometry>
                    <mesh filename="${modelPath}/meshes_v3/r_foot.dae" scale="1 1 1" />
                </geometry>
            </visual>
            <!--
            <collision>
                <origin xyz="0 0 0" rpy="0 -0 0" />
                <geometry>
                    <mesh filename="${modelPath}/meshes_v3/r_foot.stl" scale="1 1 1" />
                </geometry>
            </collision>
            -->
            <collision>
              <origin rpy="0 0 0 " xyz="0.049 0 -0.053"/>
              <geometry name="r_foot">
                <box size="0.27 0.1301 0.056"/>
              </geometry>
            </collision>
        </link>
        <link name="r_lglut">
            <inertial>
                <mass value="0.866" />
                <origin xyz="0.0133341 -0.0170484 -0.0312052" rpy="0 -0 0" />
                <inertia ixx="0.000691326" ixy="2.24344e-05" ixz="2.50508e-06" iyy="0.00126856" iyz="-0.000137862" izz="0.00106487" />
            </inertial>
            <visual>
                <origin xyz="0 0 0" rpy="0 -0 0" />
                <geometry>
                    <mesh filename="${modelPath}/meshes_v3/r_lglut.dae" scale="1 1 1" />
                </geometry>
            </visual>
            <collision>
                <origin xyz="0 0 0" rpy="0 -0 0" />
                <geometry>
                    <mesh filename="${modelPath}/meshes_v3/r_lglut.stl" scale="1 1 1" />
                </geometry>
            </collision>
        </link>
        <link name="r_lleg">
            <inertial>
                <mass value="5.479" />
                <origin xyz="0.001 0 -0.187" rpy="0 -0 0" />
                <inertia ixx="0.077" ixy="-0" ixz="-0.003" iyy="0.076" iyz="-0" izz="0.01" />
            </inertial>
            <visual>
                <origin xyz="0 0 0" rpy="0 -0 0" />
                <geometry>
                    <mesh filename="${modelPath}/meshes_v3/r_lleg.dae" scale="1 1 1" />
                </geometry>
            </visual>
            <collision>
                <origin xyz="0 0 0" rpy="0 -0 0" />
                <geometry>
                    <mesh filename="${modelPath}/meshes_v3/r_lleg.stl" scale="1 1 1" />
                </geometry>
            </collision>
        </link>
        <link name="r_talus">
            <inertial>
                <mass value="0.125" />
                <origin xyz="0 0 0" rpy="0 -0 0" />
                <inertia ixx="1.01674e-05" ixy="0" ixz="0" iyy="8.42775e-06" iyz="0" izz="1.30101e-05" />
            </inertial>
            <visual>
                <origin xyz="0 0 0" rpy="0 -0 0" />
                <geometry>
                    <mesh filename="${modelPath}/meshes_v3/r_talus.dae" scale="1 1 1" />
                </geometry>
            </visual>
            <collision>
                <origin xyz="0 0 0" rpy="0 -0 0" />
                <geometry>
                    <mesh filename="${modelPath}/meshes_v3/r_talus.stl" scale="1 1 1" />
                </geometry>
            </collision>
        </link>
        <link name="r_uglut">
            <inertial>
                <mass value="0.648" />
                <origin xyz="0.00529262 0.00344732 0.00313046" rpy="0 -0 0" />
                <inertia ixx="0.00074276" ixy="3.79607e-08" ixz="-2.79549e-05" iyy="0.000688179" iyz="3.2735e-08" izz="0.00041242" />
            </inertial>
            <visual>
                <origin xyz="0 0 0" rpy="0 -0 0" />
                <geometry>
                    <mesh filename="${modelPath}/meshes_v3/r_uglut.dae" scale="1 1 1" />hhffggg
                </geometry>
            </visual>
            <collision>
                <origin xyz="0 0 0" rpy="0 -0 0" />
                <geometry>
                    <mesh filename="${modelPath}/meshes_v3/r_uglut.stl" scale="1 1 1" />
                </geometry>
            </collision>
        </link>
        <link name="r_uleg">
            <inertial>
                <mass value="9.209" />
                <origin xyz="0 0 -0.21" rpy="0 -0 0" />
                <inertia ixx="0.09" ixy="0" ixz="0" iyy="0.09" iyz="0" izz="0.02" />
            </inertial>
            <visual>
                <origin xyz="0 0 0" rpy="0 -0 0" />
                <geometry>
                    <mesh filename="${modelPath}/meshes_v3/r_uleg.dae" scale="1 1 1" />
                </geometry>
            </visual>
            <collision>
                <origin xyz="0 0 0" rpy="0 -0 0" />
                <geometry>
                    <mesh filename="${modelPath}/meshes_v3/r_uleg.stl" scale="1 1 1" />
                </geometry>
            </collision>
        </link>
        <joint name="l_leg_akx" type="revolute">
            <origin xyz="0 0 0" rpy="0 -0 0" />
            <axis xyz="1 0 0" />
            <parent link="l_talus" />
            <child link="l_foot" />
            <dynamics damping="0.1" friction="0" />
            <limit effort="90" velocity="12" lower="-0.8" upper="0.8" />
            <safety_controller k_position="100" k_velocity="100" soft_lower_limit="-10.8" soft_upper_limit="10.8" />
        </joint>
        <joint name="l_leg_aky" type="revolute">
            <origin xyz="0 0 -0.422" rpy="0 -0 0" />
            <axis xyz="0 1 0" />
            <parent link="l_lleg" />
            <child link="l_talus" />
            <dynamics damping="0.1" friction="0" />
            <limit effort="700" velocity="12" lower="-1" upper="0.7" />
            <safety_controller k_position="100" k_velocity="100" soft_lower_limit="-11" soft_upper_limit="10.7" />
        </joint>
        <joint name="l_leg_hpx" type="revolute">
            <origin xyz="0 0 0" rpy="0 -0 0" />
            <axis xyz="1 0 0" />
            <parent link="l_uglut" />
            <child link="l_lglut" />
            <dynamics damping="0.1" friction="0" />
            <limit effort="180" velocity="12" lower="-0.523599" upper="0.523599" />
            <safety_controller k_position="100" k_velocity="100" soft_lower_limit="-10.5236" soft_upper_limit="10.5236" />
        </joint>
        <joint name="l_leg_hpy" type="revolute">
            <origin xyz="0.05 0 -0.05" rpy="0 -0 0" />
            <axis xyz="0 1 0" />
            <parent link="l_lglut" />
            <child link="l_uleg" />
            <dynamics damping="0.1" friction="0" />
            <limit effort="260" velocity="12" lower="-1.72072" upper="0.524821" />
            <safety_controller k_position="100" k_velocity="100" soft_lower_limit="-11.7207" soft_upper_limit="10.5248" />
        </joint>

        <joint name="l_leg_hpz" type="revolute">
            <origin xyz="0 0.089 0" rpy="0 -0 0" />
            <axis xyz="0 0 1" />
            <parent link="pelvis" />
            <child link="l_uglut" />
            <dynamics damping="0.1" friction="0" />
            <limit effort="110" velocity="12" lower="-0.174533" upper="1.22173" />
            <safety_controller k_position="100" k_velocity="100" soft_lower_limit="-10.1745" soft_upper_limit="11.2217" />
        </joint>

        <joint name="l_leg_kny" type="revolute">
            <origin xyz="-0.05 0 -0.374" rpy="0 -0 0" />
            <axis xyz="0 1 0" />
            <parent link="l_uleg" />
            <child link="l_lleg" />
            <dynamics damping="0.1" friction="0" />
            <limit effort="220" velocity="12" lower="0" upper="2.38569" />
            <safety_controller k_position="100" k_velocity="100" soft_lower_limit="-10" soft_upper_limit="12.3857" />
        </joint>
        <joint name="r_leg_akx" type="revolute">
            <origin xyz="0 0 0" rpy="0 -0 0" />
            <axis xyz="1 0 0" />
            <parent link="r_talus" />
            <child link="r_foot" />
            <dynamics damping="0.1" friction="0" />
            <limit effort="90" velocity="12" lower="-0.8" upper="0.8" />
            <safety_controller k_position="100" k_velocity="100" soft_lower_limit="-10.8" soft_upper_limit="10.8" />
        </joint>
        <joint name="r_leg_aky" type="revolute">
            <origin xyz="0 0 -0.422" rpy="0 -0 0" />
            <axis xyz="0 1 0" />
            <parent link="r_lleg" />
            <child link="r_talus" />
            <dynamics damping="0.1" friction="0" />
            <limit effort="700" velocity="12" lower="-1" upper="0.7" />
            <safety_controller k_position="100" k_velocity="100" soft_lower_limit="-11" soft_upper_limit="10.7" />
        </joint>
        <joint name="r_leg_hpx" type="revolute">
            <origin xyz="0 0 0" rpy="0 -0 0" />
            <axis xyz="1 0 0" />
            <parent link="r_uglut" />
            <child link="r_lglut" />
            <dynamics damping="0.1" friction="0" />
            <limit effort="180" velocity="12" lower="-0.523599" upper="0.523599" />
            <safety_controller k_position="100" k_velocity="100" soft_lower_limit="-10.5236" soft_upper_limit="10.5236" />
        </joint>
        <joint name="r_leg_hpy" type="revolute">
            <origin xyz="0.05 0 -0.05" rpy="0 -0 0" />
            <axis xyz="0 1 0" />
            <parent link="r_lglut" />
            <child link="r_uleg" />
            <dynamics damping="0.1" friction="0" />
            <limit effort="260" velocity="12" lower="-1.72072" upper="0.524821" />
            <safety_controller k_position="100" k_velocity="100" soft_lower_limit="-11.7207" soft_upper_limit="10.5248" />
        </joint>
        <joint name="r_leg_hpz" type="revolute">
            <origin xyz="0 -0.089 0" rpy="0 -0 0" />
            <axis xyz="0 0 1" />
            <parent link="pelvis" />
            <child link="r_uglut" />
            <dynamics damping="0.1" friction="0" />
            <limit effort="110" velocity="12" lower="-1.22173" upper="0.174533" />
            <safety_controller k_position="100" k_velocity="100" soft_lower_limit="-11.2217" soft_upper_limit="10.1745" />
        </joint>
        <joint name="r_leg_kny" type="revolute">
            <origin xyz="-0.05 0 -0.374" rpy="0 -0 0" />
            <axis xyz="0 1 0" />
            <parent link="r_uleg" />
            <child link="r_lleg" />
            <dynamics damping="0.1" friction="0" />
            <limit effort="220" velocity="12" lower="0" upper="2.38569" />
            <safety_controller k_position="100" k_velocity="100" soft_lower_limit="-10" soft_upper_limit="12.3857" />
        </joint>
    </macro>
</robot>
