<?xml version="1.0" ?>
<!-- =================================================================================== -->
<!-- |    This document was autogenerated by xacro from uta.urdf.xacro                 | -->
<!-- |    EDITING THIS FILE BY HAND IS NOT RECOMMENDED                                 | -->
<!-- =================================================================================== -->
<robot name="hume" xmlns:controller="http://playerstage.sourceforge.net/gazebo/xmlschema/#controller" xmlns:interface="http://playerstage.sourceforge.net/gazebo/xmlschema/#interface" xmlns:sensor="http://playerstage.sourceforge.net/gazebo/xmlschema/#sensor" xmlns:xacro="http://playerstage.sourceforge.net/gazebo/xmlschema/#interface">

<!--!!!!!!!!!!!!!!!!!!!!!RIGHT LEG TRANSMISSIONS!!!!!!!!!!!!!!!!!!!!!!!!!!!!!!!!!!!!!!!!!!!!!!!!-->
<!--    <transmission name="torso_to_abduct_r_t" type="pr2_mechanism_model/SimpleTransmission">
    <actuator name="torso_to_abduct_r_a"/>
    <joint name="torso_to_abduct_r_j"/>
  <mechanicalReduction>1</mechanicalReduction>
  </transmission>
 	<transmission name="abduct_r_to_thigh_r_t" type="pr2_mechanism_model/SimpleTransmission">
    <actuator name="abduct_r_to_thigh_r_a"/>
    <joint name="abduct_r_to_thigh_r_j"/>
  <mechanicalReduction>1</mechanicalReduction>
  </transmission>
  <transmission name="thigh_r_to_knee_r_t" type="pr2_mechanism_model/SimpleTransmission">
    <actuator name="thigh_r_to_knee_r_a"/>
    <joint name="thigh_r_to_knee_r_j"/>
  <mechanicalReduction>1</mechanicalReduction>
  </transmission> -->

<!--!!!!!!!!!!!!!!!!!!!!!LEFT LEG TRANSMISSIONS!!!!!!!!!!!!!!!!!!!!!!!!!!!!!!!!!!!!!!!!!!!!!!!!-->
<!--   <transmission name="torso_to_abduct_l_t" type="pr2_mechanism_model/SimpleTransmission">
    <actuator name="torso_to_abduct_l_a"/>
    <joint name="torso_to_abduct_l_j"/>
  <mechanicalReduction>1</mechanicalReduction>
  </transmission>
 	<transmission name="abduct_l_to_thigh_l_t" type="pr2_mechanism_model/SimpleTransmission">
    <actuator name="abduct_l_to_thigh_l_a"/>
    <joint name="abduct_l_to_thigh_l_j"/>
  <mechanicalReduction>1</mechanicalReduction>
  </transmission>
  <transmission name="thigh_l_to_knee_l_t" type="pr2_mechanism_model/SimpleTransmission">
    <actuator name="thigh_l_to_knee_l_a"/>
    <joint name="thigh_l_to_knee_l_j"/>
  <mechanicalReduction>1</mechanicalReduction>
  </transmission>
 -->

  <link name="torso">
    <inertial>
      <mass value="7.30586"/>
      <origin xyz="0.00347 0.22524 0.00522"/>
      <inertia ixx="0.156380" ixy="0" ixz="0" iyy="0.0596218" iyz="0" izz="0.1814431"/>
    </inertial>
    <visual>
      <origin rpy="1.5702 0 0 " xyz="0 0 -0.0"/>
      <geometry name="torso_geom">
        <mesh filename="package://hume_meshes/UMB_SM_torso_GJ.STL"/>
      </geometry>
    </visual>
    <collision>
      <origin rpy="0.0 0.0 0.0 " xyz="0 0 0.25"/>
      <geometry name="torso_collision_geom">
      	<box size ="0.2794 0.1 0.4"/>
      </geometry>
    </collision>
  </link>

<!--!!!!!!!!!!!!!!!!!!!!!RIGHT LEG!!!!!!!!!!!!!!!!!!!!!!!!!!!!!!!!!!!!!!!!!!!!!!!!-->
	<joint name="torso_to_abduct_r_j" type="continuous">
    <axis xyz="0 1 0"/>
    <origin rpy="0 0 0" xyz="-0.1397 0.0 0.0"/>
    <parent link="torso"/>
    <child link="abduct_r"/>
<!--    <dynamics damping="1.0"/>-->
  </joint>
  <link name="abduct_r">
    <inertial>
      <mass value="2.294"/>
      <origin xyz="0.00075 0.03416 0.04293"/>
      <inertia ixx="0.003724" ixy="0.0" ixz="0.0" iyy="0.01391" iyz="0.0" izz="0.01356"/>
    </inertial>
    <visual>
      <origin rpy="1.5702 0 0 " xyz="0 0 -0.03535"/>
      <geometry name="abduct_r_geom">
        <mesh filename="package://hume_meshes/UMB_SM_abduction_GJ.STL"/>
      </geometry>
    </visual>
    <collision>
      <origin rpy="1.507 0.0 0.0 " xyz="0 0 .05"/>
      <geometry name="abduct_r_collision_geom">
        <cylinder length="0.2" radius="0.05"/>
      </geometry>
    </collision>
  </link>
	<joint name="abduct_r_to_thigh_r_j" type="continuous">
    <axis xyz="1 0 0"/>
    <origin rpy="0 0 0" xyz="0.0 0.0 -0.03535"/>
    <parent link="abduct_r"/>
    <child link="thigh_r"/>
<!--    <dynamics damping="1.0"/>-->
  </joint>
  <link name="thigh_r">
    <inertial>
      <mass value="2.242"/>
      <origin xyz="0.000075 -0.000018 -0.14777"/>
      <inertia ixx="0.038482" ixy="0" ixz="0.0" iyy="0.039835" iyz="0" izz="0.0042934"/>
    </inertial>
    <visual>
      <origin rpy="1.5702 0 0 " xyz="0 0 0.0"/>
      <geometry name="thigh_r_geom">
        <mesh filename="package://hume_meshes/UMB_SM_thigh_GJ.STL"/>
      </geometry>
    </visual>
    <collision>
      <origin rpy="0.0 0.0 0.0 " xyz="0 0 -0.2"/>
      <geometry name="thigh_r_collision_geom">
        <cylinder length="0.455" radius="0.05"/>
      </geometry>
    </collision>
  </link>
	<joint name="thigh_r_to_knee_r_j" type="continuous">
    <axis xyz="1 0 0"/>
    <origin rpy="0 0 0" xyz="0.0 -0.0181 -0.450"/>
    <parent link="thigh_r"/>
    <child link="knee_r"/>
<!--    <dynamics damping="1.0"/>-->
  </joint>
  <link name="knee_r">
    <inertial>
      <mass value="0.3158"/>
      <origin xyz="0.00002 -0.00295 -0.06479"/>
      <inertia ixx="0.006581" ixy="0" ixz="0.0" iyy="0.006667" iyz="0" izz="0.000208"/>
    </inertial>
    <visual>
      <origin rpy="1.5702 0 0 " xyz="0 0.0181 0.450"/>
      <geometry name="knee_r_geom">
        <mesh filename="package://hume_meshes/UMB_SM_knee_GJ.STL"/>
      </geometry>
    </visual>
    <collision>
      <origin rpy="0.0 0.0 0.0 " xyz="0 0 -0.450"/>
      <geometry name="knee_l_collision_geom">
        <sphere radius="0.0174"/>
      </geometry>
    </collision>
  </link>

<!--!!!!!!!!!!!!!!!!!!!!!LEFT LEG!!!!!!!!!!!!!!!!!!!!!!!!!!!!!!!!!!!!!!!!!!!!!!!!-->
	<joint name="torso_to_abduct_l_j" type="continuous">
    <axis xyz="0 1 0"/>
    <origin rpy="0 0 0" xyz="0.1397 0.0 0.0"/>
    <parent link="torso"/>
    <child link="abduct_l"/>
  </joint>
  <link name="abduct_l">
    <inertial>
      <mass value="2.294"/>
      <origin xyz="0.00075 0.03416 0.04293"/>
      <inertia ixx="0.003724" ixy="0.0" ixz="0.0" iyy="0.01391" iyz="0.0" izz="0.01356"/>
    </inertial>
    <visual>
      <origin rpy="1.5702 0 0 " xyz="0 0 -0.03535"/>
      <geometry name="abduct_l_geom">
        <mesh filename="package://hume_meshes/UMB_SM_abduction_GJ.STL"/>
      </geometry>
    </visual>
    <collision>
      <origin rpy="1.507 0.0 0.0 " xyz="0 0 .05"/>
      <geometry name="abduct_l_collision_geom">
        <cylinder length="0.2" radius="0.05"/>
      </geometry>
    </collision>
  </link>
	<joint name="abduct_l_to_thigh_l_j" type="continuous">
    <axis xyz="1 0 0"/>
    <origin rpy="0 0 0" xyz="0.0 0.0 -0.03535"/>
    <parent link="abduct_l"/>
    <child link="thigh_l"/>
  </joint>
  <link name="thigh_l">
    <inertial>
      <mass value="2.242"/>
      <origin xyz="0.000075 -0.000018 -0.14777"/>
      <inertia ixx="0.038482" ixy="0" ixz="0.0" iyy="0.039835" iyz="0" izz="0.0042934"/>
    </inertial>
    <visual>
      <origin rpy="1.5702 0 0 " xyz="0 0 0.0"/>
      <geometry name="thigh_l_geom">
        <mesh filename="package://hume_meshes/UMB_SM_thigh_GJ.STL"/>
      </geometry>
    </visual>
    <collision>
      <origin rpy="0.0 0.0 0.0 " xyz="0 0 -0.2"/>
      <geometry name="thigh_l_collision_geom">
        <cylinder length="0.455" radius="0.05"/>
      </geometry>
    </collision>
  </link>
	<joint name="thigh_l_to_knee_l_j" type="continuous">
    <axis xyz="1 0 0"/>
    <origin rpy="0 0 0" xyz="0.0 -0.0181 -0.450"/>
    <parent link="thigh_l"/>
    <child link="knee_l"/>
  </joint>
  <link name="knee_l">
    <inertial>
      <mass value="0.3158"/>
      <origin xyz="0.00002 -0.00295 -0.06479"/>
      <inertia ixx="0.006581" ixy="0" ixz="0.0" iyy="0.006667" iyz="0" izz="0.000208"/>
    </inertial>
    <visual>
      <origin rpy="1.5702 0 0 " xyz="0 0.0181 0.450"/>
      <geometry name="knee_l_geom">
        <mesh filename="package://hume_meshes/UMB_SM_knee_GJ.STL"/>
      </geometry>
    </visual>
    <collision>
      <origin rpy="0.0 0.0 0.0 " xyz="0 0 -0.450"/>
      <geometry name="knee_l_collision_geom">
        <sphere radius="0.0174"/>
      </geometry>
    </collision>
  </link>

  <gazebo version="1.2">
    <!-- <plugin filename="libhume_plugin.so" name="hume_plugin"/> -->
    <plugin filename="libPinPlugin.so" name="PinPlugin">
      <node>/pin_plugin</node>
    </plugin>
  </gazebo>
</robot>
