<?xml version="1.0" ?>
<!-- =================================================================================== -->
<!-- |    This document was autogenerated by xacro from xacro/V1_gazebo.xacro          | -->
<!-- |    EDITING THIS FILE BY HAND IS NOT RECOMMENDED                                 | -->
<!-- =================================================================================== -->
<robot name="v1" xmlns:controller="http://playerstage.sourceforge.net/gazebo/xmlschema/#controller" xmlns:interface="http://playerstage.sourceforge.net/gazebo/xmlschema/#interface" xmlns:sensor="http://playerstage.sourceforge.net/gazebo/xmlschema/#sensor" xmlns:xacro="http://www.ros.org/wiki/xacro">

  <link name="v1/Pelvis">
    <inertial>
      <mass value="5.15"/>
      <origin rpy="0 0 0" xyz="0.0005 -0.0009 -0.0704"/>
      <inertia ixx="0.109221629167" ixy="0.0" ixz="0.0" iyy="0.0928072916667" iyz="0.0" izz="0.0851573958333"/>
    </inertial>
    <visual>
      <geometry>
        <mesh filename="${modelPath}/meshes/2013_05_16/pelvis.stl"/>
        <!-- <box size="${width} ${height} ${depth}"/> -->
      </geometry>
      <origin rpy="0 0 0" xyz="0 0 0"/>
      <!-- <origin rpy="${origin_rpy}" xyz="${origin_xyz}"/> -->
      <material name="White"/>
    </visual>
    <collision>
      <geometry>
        <mesh filename="${modelPath}/meshes/2013_05_16/pelvis.stl"/>
      </geometry>
      <origin rpy="0 0 0" xyz="0 0 0"/>
    </collision>
  </link>
  <gazebo reference="v1/Pelvis">
    <material>Gazebo/White</material>
  </gazebo>

  <link name="v1/WaistRotator">
    <!-- Virtual Link -->
    <inertial>
      <mass value="0.1"/>
      <origin rpy="0 0 0" xyz="0 0 0"/>
      <inertia ixx="8.33333333333e-05" ixy="0.0" ixz="0.0" iyy="8.33333333333e-05" iyz="0.0" izz="0.000125"/>
    </inertial>
  </link>
  <link name="v1/WaistExtensor">
    <!-- Virtual Link -->
    <inertial>
      <mass value="0.1"/>
      <origin rpy="0 0 0" xyz="0 0 0"/>
      <inertia ixx="8.33333333333e-05" ixy="0.0" ixz="0.0" iyy="8.33333333333e-05" iyz="0.0" izz="0.000125"/>
    </inertial>
  </link>
  <joint name="WaistRotator" type="revolute">
    <origin rpy="0 0 0" xyz="0 0 0"/>
    <axis xyz="0 0 1"/>
    <parent link="v1/Pelvis"/>
    <child link="v1/WaistRotator"/>
    <limit effort="190" lower="-0.6981317004" upper="0.6981317004" velocity="5.89"/>
    <controller_gains Kd="400" Kp="20000"/>
    <dynamics damping="1.0" friction="0.0"/>
  </joint>
  <gazebo reference="WaistRotator">
    <provideFeedback>1</provideFeedback>
  </gazebo>

  <joint name="WaistExtensor" type="revolute">
    <origin rpy="1.57079632679 0 0" xyz="0.04191 0 0"/>
    <axis xyz="0 0 1"/>
    <parent link="v1/WaistRotator"/>
    <child link="v1/WaistExtensor"/>
    <limit effort="150" lower="-0.6981317004" upper="0.08726646255" velocity="9"/>
    <controller_gains Kd="400" Kp="20000"/>
    <dynamics damping="1.0" friction="0.0"/>
  </joint>
  <gazebo reference="WaistExtensor">
    <provideFeedback>1</provideFeedback>
  </gazebo>

  <joint name="WaistLateralExtensor" type="revolute">
    <origin rpy="1.57079632679 0 1.57079632679" xyz="0 0.020352 0"/>
    <axis xyz="0 0 1"/>
    <parent link="v1/WaistExtensor"/>
    <child link="v1/Trunk"/>
    <limit effort="150" lower="-0.26179938765" upper="0.26179938765" velocity="9"/>
    <controller_gains Kd="400" Kp="20000"/>
    <dynamics damping="1.0" friction="0.0"/>
  </joint>
  <gazebo reference="WaistLateralExtensor">
    <provideFeedback>1</provideFeedback>
  </gazebo>


  <transmission name="WaistRotatorTransmission">
    <type>transmission_interface/SimpleTransmission</type>
    <joint name="WaistRotator"/>
    <actuator name="/pelvis/wj1">
      <hardwareInterface>EffortJointInterface</hardwareInterface>
      <mechanicalReduction>100</mechanicalReduction>
    </actuator>
    <motorTorqueConstant>0.01</motorTorqueConstant>
  </transmission>
  <transmission name="WaistExtensorTransmission">
    <type>transmission_interface/SimpleTransmission</type>
    <joint name="WaistExtensor"/>
    <actuator name="/trunk/wj2">
      <hardwareInterface>EffortJointInterface</hardwareInterface>
      <mechanicalReduction>100</mechanicalReduction>
    </actuator>
    <motorTorqueConstant>0.01</motorTorqueConstant>
  </transmission>
  <transmission name="WaistLateralExtensorTransmission">
    <type>transmission_interface/SimpleTransmission</type>
    <joint name="WaistLateralExtensor"/>
    <actuator name="/trunk/wj3">
      <hardwareInterface>EffortJointInterface</hardwareInterface>
      <mechanicalReduction>100</mechanicalReduction>
    </actuator>
    <motorTorqueConstant>0.01</motorTorqueConstant>
  </transmission>


  <link name="v1/RightHipRotator">
    <inertial>
      <mass value="2.39"/>
      <origin rpy="0 0 0" xyz="0.001307857 0.021764163 0.038670367"/>
      <inertia ixx="0.0172609783333" ixy="0.0" ixz="0.0" iyy="0.0148661983333" iyz="0.0" izz="0.0112381783333"/>
    </inertial>
    <visual>
      <geometry>
        <mesh filename="${modelPath}/meshes/2013_05_16/lj1_Right.stl"/>
        <!-- <box size="${width} ${height} ${depth}"/> -->
      </geometry>
      <origin rpy="0 0 0" xyz="0 0 0"/>
      <!-- <origin rpy="${origin_rpy}" xyz="${origin_xyz}"/> -->
      <material name="Gold"/>
    </visual>
    <collision>
      <geometry>
        <mesh filename="${modelPath}/meshes/2013_05_16/lj1_Right.stl"/>
      </geometry>
      <origin rpy="0 0 0" xyz="0 0 0"/>
    </collision>
  </link>
  <gazebo reference="v1/RightHipRotator">
    <material>Gazebo/Gold</material>
  </gazebo>

  <link name="v1/RightHipAdductor">
    <inertial>
      <mass value="5.15"/>
      <origin rpy="0 0 0" xyz="0.024260044 0.019261751 -0.0018458616"/>
      <inertia ixx="0.0211810916667" ixy="0.0" ixz="0.0" iyy="0.0138577916667" iyz="0.0" izz="0.0220531583333"/>
    </inertial>
    <visual>
      <geometry>
        <mesh filename="${modelPath}/meshes/2013_05_16/lj2.stl"/>
        <!-- <box size="${width} ${height} ${depth}"/> -->
      </geometry>
      <origin rpy="0 0 0" xyz="0 0 0"/>
      <!-- <origin rpy="${origin_rpy}" xyz="${origin_xyz}"/> -->
      <material name="White"/>
    </visual>
    <collision>
      <geometry>
        <mesh filename="${modelPath}/meshes/2013_05_16/lj2.stl"/>
      </geometry>
      <origin rpy="0 0 0" xyz="0 0 0"/>
    </collision>
  </link>
  <gazebo reference="v1/RightHipAdductor">
    <material>Gazebo/White</material>
  </gazebo>

  <link name="v1/RightLeg">
    <inertial>
      <mass value="7.14"/>
      <origin rpy="0 0 0" xyz="0.25533364 -0.016460667 -0.035"/>
      <inertia ixx="0.065433935" ixy="0.0" ixz="0.0" iyy="0.2413439" iyz="0.0" izz="0.258221075"/>
    </inertial>
    <visual>
      <geometry>
        <mesh filename="${modelPath}/meshes/2013_05_16/lj3_Right.stl"/>
        <!-- <box size="${width} ${height} ${depth}"/> -->
      </geometry>
      <origin rpy="0 0 0" xyz="0 0 0"/>
      <!-- <origin rpy="${origin_rpy}" xyz="${origin_xyz}"/> -->
      <material name="White"/>
    </visual>
    <collision>
      <geometry>
        <mesh filename="${modelPath}/meshes/2013_05_16/lj3_Right.stl"/>
      </geometry>
      <origin rpy="0 0 0" xyz="0 0 0"/>
    </collision>
  </link>
  <gazebo reference="v1/RightLeg">
    <material>Gazebo/White</material>
  </gazebo>

  <link name="v1/RightShankStructure">
    <inertial>
      <mass value="6.902"/>
      <origin rpy="0 0 0" xyz="0.12342688 -0.0087741035 0.006614093"/>
      <inertia ixx="0.0435245871667" ixy="0.0" ixz="0.0" iyy="0.120902909167" iyz="0.0" izz="0.11978421"/>
    </inertial>
    <visual>
      <geometry>
        <mesh filename="${modelPath}/meshes/2013_05_16/lj4_Right.stl"/>
        <!-- <box size="${width} ${height} ${depth}"/> -->
      </geometry>
      <origin rpy="0 0 0" xyz="0 0 0"/>
      <!-- <origin rpy="${origin_rpy}" xyz="${origin_xyz}"/> -->
      <material name="White"/>
    </visual>
    <collision>
      <geometry>
        <mesh filename="${modelPath}/meshes/2013_05_16/lj4_Right.stl"/>
      </geometry>
      <origin rpy="0 0 0" xyz="0 0 0"/>
    </collision>
  </link>
  <gazebo reference="v1/RightShankStructure">
    <material>Gazebo/White</material>
  </gazebo>

  <link name="v1/RightAnkleYoke">
    <inertial>
      <mass value="0.395"/>
      <origin rpy="0 0 0" xyz="0.0057963439 0.0020433211 9.0424431e-05"/>
      <inertia ixx="0.000210699583333" ixy="0.0" ixz="0.0" iyy="5.64191666667e-05" iyz="0.0" izz="0.000225972916667"/>
    </inertial>
    <visual>
      <geometry>
        <box size="0.033 0.076 0.025"/>
      </geometry>
      <origin rpy="0 0 0" xyz="0.0057963439 0.0020433211 9.0424431e-05"/>
      <material name="Gray"/>
    </visual>
    <collision>
      <geometry>
        <box size="0.033 0.076 0.025"/>
      </geometry>
      <origin rpy="0 0 0" xyz="0.0057963439 0.0020433211 9.0424431e-05"/>
    </collision>
  </link>

  <link name="v1/RightUpperFoot">
    <inertial>
      <mass value="1.888"/>
      <origin rpy="0 0 0" xyz="0.048263578 -3.1591183e-05 0.077849126"/>
      <inertia ixx="0.0167377493333" ixy="0.0" ixz="0.0" iyy="0.0152179093333" iyz="0.0" izz="0.00363565866667"/>
    </inertial>
    <visual>
      <geometry>
        <mesh filename="${modelPath}/meshes/2013_05_16/lj6_Right.stl"/>
        <!-- <box size="${width} ${height} ${depth}"/> -->
      </geometry>
      <origin rpy="0 0 0" xyz="0 0 0"/>
      <!-- <origin rpy="${origin_rpy}" xyz="${origin_xyz}"/> -->
      <material name="White"/>
    </visual>
    <collision>
      <origin rpy="0 0 0" xyz="0.048263578 -3.1591183e-05 0.077849126"/>
      <geometry>
        <box size="0.082 0.128 0.3"/>
      </geometry>
    </collision>
  </link>
  <gazebo reference="v1/RightUpperFoot">
    <material>Gazebo/White</material>
  </gazebo>
  <gazebo reference="v1/RightUpperFoot">
    <kp>100000.0</kp>
    <kd>1000.0</kd>
    <mu1>1.5</mu1>
    <mu2>1.5</mu2>
    <fdir1>0 0 1</fdir1>
    <maxVel>1.0</maxVel>
    <minDepth>0.00</minDepth>
  </gazebo>

  <joint name="RightHipRotator" type="revolute">
    <origin rpy="0.0 0 -1.57079632679" xyz="0 -0.1016 -0.183"/>
    <axis xyz="0 0 1"/>
    <parent link="v1/Pelvis"/>
    <child link="v1/RightHipRotator"/>
    <limit effort="190" lower="-1.0471975506" upper="0.5235987753" velocity="5.89"/>
    <controller_gains Kd="500" Kp="15000"/>
    <dynamics damping="1.0" friction="0.0"/>
  </joint>
  <gazebo reference="RightHipRotator">
    <provideFeedback>1</provideFeedback>
  </gazebo>

  <joint name="RightHipAdductor" type="revolute">
    <origin rpy="-1.57079632679 0 0" xyz="0 0 0"/>
    <axis xyz="0 0 1"/>
    <parent link="v1/RightHipRotator"/>
    <child link="v1/RightHipAdductor"/>
    <limit effort="350" lower="-0.5235987753" upper="0.26179938765" velocity="7"/>
    <controller_gains Kd="500" Kp="15000"/>
    <dynamics damping="1.0" friction="0.0"/>
  </joint>
  <gazebo reference="RightHipAdductor">
    <provideFeedback>1</provideFeedback>
  </gazebo>

  <joint name="RightHipExtensor" type="revolute">
    <origin rpy="-1.57079632679 0 1.57079632679" xyz="0 0.061 0"/>
    <axis xyz="0 0 1"/>
    <parent link="v1/RightHipAdductor"/>
    <child link="v1/RightLeg"/>
    <limit effort="350" lower="-2.35619448885" upper="1.71042266598" velocity="6.11"/>
    <controller_gains Kd="500" Kp="15000"/>
    <dynamics damping="1.0" friction="0.0"/>
  </joint>
  <gazebo reference="RightHipExtensor">
    <provideFeedback>1</provideFeedback>
  </gazebo>

  <joint name="RightKneeExtensor" type="revolute">
    <origin rpy="3.14159265359 0 0" xyz="0.431 0 -0.0374"/>
    <axis xyz="0 0 1"/>
    <parent link="v1/RightLeg"/>
    <child link="v1/RightShankStructure"/>
    <limit effort="350" lower="-1.90240888359" upper="0.218166156375" velocity="6.11"/>
    <controller_gains Kd="500" Kp="15000"/>
    <dynamics damping="1.0" friction="0.0"/>
  </joint>
  <gazebo reference="RightKneeExtensor">
    <provideFeedback>1</provideFeedback>
  </gazebo>

  <joint name="RightAnkleExtensor" type="revolute">
    <origin rpy="3.14159265359 0 0.13" xyz="0.406 0 0"/>
    <axis xyz="0 0 1"/>
    <parent link="v1/RightShankStructure"/>
    <child link="v1/RightAnkleYoke"/>
    <limit effort="205" lower="-0.8726646255" upper="0.8726646255" velocity="11"/>
    <controller_gains Kd="400" Kp="15000"/>
    <dynamics damping="1.0" friction="0.0"/>
  </joint>
  <gazebo reference="RightAnkleExtensor">
    <provideFeedback>1</provideFeedback>
  </gazebo>

  <joint name="RightAnkle" type="revolute">
    <origin rpy="1.57079632679 0 0" xyz="0.0127 0 0"/>
    <axis xyz="0 0 1"/>
    <parent link="v1/RightAnkleYoke"/>
    <child link="v1/RightUpperFoot"/>
    <limit effort="205" lower="-0.3490658502" upper="0.3490658502" velocity="11"/>
    <controller_gains Kd="400" Kp="15000"/>
    <dynamics damping="1.0" friction="0.0"/>
  </joint>
  <gazebo reference="RightAnkle">
    <provideFeedback>1</provideFeedback>
  </gazebo>

  <transmission name="RightHipRotatorTransmission">
    <type>transmission_interface/SimpleTransmission</type>
    <joint name="RightHipRotator"/>
    <actuator name="/pelvis/rj1">
      <hardwareInterface>EffortJointInterface</hardwareInterface>
      <mechanicalReduction>100</mechanicalReduction>
    </actuator>
    <motorTorqueConstant>0.01</motorTorqueConstant>
  </transmission>

  <transmission name="RightHipAdductorTransmission">
    <type>transmission_interface/SimpleTransmission</type>
    <joint name="RightHipAdductor"/>
    <actuator name="/right_leg/j2">
      <hardwareInterface>EffortJointInterface</hardwareInterface>
      <mechanicalReduction>100</mechanicalReduction>
    </actuator>
    <motorTorqueConstant>0.01</motorTorqueConstant>
  </transmission>

  <transmission name="RightHipExtensorTransmission">
    <type>transmission_interface/SimpleTransmission</type>
    <joint name="RightHipExtensor"/>
    <actuator name="/right_leg/j3">
      <hardwareInterface>EffortJointInterface</hardwareInterface>
      <mechanicalReduction>100</mechanicalReduction>
    </actuator>
    <motorTorqueConstant>0.01</motorTorqueConstant>
  </transmission>

  <transmission name="RightKneeExtensorTransmission">
    <type>transmission_interface/SimpleTransmission</type>
    <joint name="RightKneeExtensor"/>
    <actuator name="/right_leg/j4">
      <hardwareInterface>EffortJointInterface</hardwareInterface>
      <mechanicalReduction>100</mechanicalReduction>
    </actuator>
    <motorTorqueConstant>0.01</motorTorqueConstant>
  </transmission>

  <transmission name="RightAnkleExtensorTransmission">
    <type>transmission_interface/SimpleTransmission</type>
    <joint name="RightAnkleExtensor"/>
    <actuator name="/right_leg/j5">
      <hardwareInterface>EffortJointInterface</hardwareInterface>
      <mechanicalReduction>100</mechanicalReduction>
    </actuator>
    <motorTorqueConstant>0.01</motorTorqueConstant>
  </transmission>

  <transmission name="RightAnkleTransmission">
    <type>transmission_interface/SimpleTransmission</type>
    <joint name="RightAnkle"/>
    <actuator name="/right_leg/j6">
      <hardwareInterface>EffortJointInterface</hardwareInterface>
      <mechanicalReduction>100</mechanicalReduction>
    </actuator>
    <motorTorqueConstant>0.01</motorTorqueConstant>
  </transmission>

  <link name="v1/LeftHipRotator">
    <inertial>
      <mass value="2.39"/>
      <origin rpy="0 0 0" xyz="0.001307857 0.021764163 -0.038670367"/>
      <inertia ixx="0.0172609783333" ixy="0.0" ixz="0.0" iyy="0.0148661983333" iyz="0.0" izz="0.0112381783333"/>
    </inertial>
    <visual>
      <geometry>
        <mesh filename="${modelPath}/meshes/2013_05_16/lj1_Left.stl"/>
        <!-- <box size="${width} ${height} ${depth}"/> -->
      </geometry>
      <origin rpy="0 0 0" xyz="0 0 0"/>
      <!-- <origin rpy="${origin_rpy}" xyz="${origin_xyz}"/> -->
      <material name="Gold"/>
    </visual>
    <collision>
      <geometry>
        <mesh filename="${modelPath}/meshes/2013_05_16/lj1_Left.stl"/>
      </geometry>
      <origin rpy="0 0 0" xyz="0 0 0"/>
    </collision>
  </link>
  <gazebo reference="v1/LeftHipRotator">
    <material>Gazebo/Gold</material>
  </gazebo>

  <link name="v1/LeftHipAdductor">
    <inertial>
      <mass value="5.15"/>
      <origin rpy="0 0 0" xyz="0.024260044 0.019261751 -0.0018458616"/>
      <inertia ixx="0.0211810916667" ixy="0.0" ixz="0.0" iyy="0.0138577916667" iyz="0.0" izz="0.0220531583333"/>
    </inertial>
    <visual>
      <geometry>
        <mesh filename="${modelPath}/meshes/2013_05_16/lj2.stl"/>
        <!-- <box size="${width} ${height} ${depth}"/> -->
      </geometry>
      <origin rpy="0 0 0" xyz="0 0 0"/>
      <!-- <origin rpy="${origin_rpy}" xyz="${origin_xyz}"/> -->
      <material name="White"/>
    </visual>
    <collision>
      <geometry>
        <mesh filename="${modelPath}/meshes/2013_05_16/lj2.stl"/>
      </geometry>
      <origin rpy="0 0 0" xyz="0 0 0"/>
    </collision>
  </link>
  <gazebo reference="v1/LeftHipAdductor">
    <material>Gazebo/White</material>
  </gazebo>

  <link name="v1/LeftLeg">
    <inertial>
      <mass value="7.14"/>
      <origin rpy="0 0 0" xyz="0.25533364 -0.016460667 0.035"/>
      <inertia ixx="0.065433935" ixy="0.0" ixz="0.0" iyy="0.2413439" iyz="0.0" izz="0.258221075"/>
    </inertial>
    <visual>
      <geometry>
        <mesh filename="${modelPath}/meshes/2013_05_16/lj3_Left.stl"/>
        <!-- <box size="${width} ${height} ${depth}"/> -->
      </geometry>
      <origin rpy="0 0 0" xyz="0 0 0"/>
      <!-- <origin rpy="${origin_rpy}" xyz="${origin_xyz}"/> -->
      <material name="White"/>
    </visual>
    <collision>
      <geometry>
        <mesh filename="${modelPath}/meshes/2013_05_16/lj3_Left.stl"/>
      </geometry>
      <origin rpy="0 0 0" xyz="0 0 0"/>
    </collision>
  </link>
  <gazebo reference="v1/LeftLeg">
    <material>Gazebo/White</material>
  </gazebo>

  <link name="v1/LeftShankStructure">
    <inertial>
      <mass value="6.902"/>
      <origin rpy="0 0 0" xyz="0.12342688 -0.0087741035 -0.006614093"/>
      <inertia ixx="0.0435245871667" ixy="0.0" ixz="0.0" iyy="0.120902909167" iyz="0.0" izz="0.11978421"/>
    </inertial>
    <visual>
      <geometry>
        <mesh filename="${modelPath}/meshes/2013_05_16/lj4_Left.stl"/>
        <!-- <box size="${width} ${height} ${depth}"/> -->
      </geometry>
      <origin rpy="0 0 0" xyz="0 0 0"/>
      <!-- <origin rpy="${origin_rpy}" xyz="${origin_xyz}"/> -->
      <material name="White"/>
    </visual>
    <collision>
      <geometry>
        <mesh filename="${modelPath}/meshes/2013_05_16/lj4_Left.stl"/>
      </geometry>
      <origin rpy="0 0 0" xyz="0 0 0"/>
    </collision>
  </link>
  <gazebo reference="v1/LeftShankStructure">
    <material>Gazebo/White</material>
  </gazebo>

  <link name="v1/LeftAnkleYoke">
    <inertial>
      <mass value="0.395"/>
      <origin rpy="0 0 0" xyz="0.0057963439 0.0020433211 9.0424431e-05"/>
      <inertia ixx="0.000210699583333" ixy="0.0" ixz="0.0" iyy="5.64191666667e-05" iyz="0.0" izz="0.000225972916667"/>
    </inertial>
    <visual>
      <geometry>
        <box size="0.033 0.076 0.025"/>
      </geometry>
      <origin rpy="0 0 0" xyz="0.0057963439 0.0020433211 9.0424431e-05"/>
      <material name="Gray"/>
    </visual>
    <collision>
      <geometry>
        <box size="0.033 0.076 0.025"/>
      </geometry>
      <origin rpy="0 0 0" xyz="0.0057963439 0.0020433211 9.0424431e-05"/>
    </collision>
  </link>

  <link name="v1/LeftUpperFoot">
    <inertial>
      <mass value="1.888"/>
      <origin rpy="0 0 0" xyz="0.048263578 -3.1591183e-05 -0.077849126"/>
      <inertia ixx="0.0167377493333" ixy="0.0" ixz="0.0" iyy="0.0152179093333" iyz="0.0" izz="0.00363565866667"/>
    </inertial>
    <visual>
      <geometry>
        <mesh filename="${modelPath}/meshes/2013_05_16/lj6_Left.stl"/>
        <!-- <box size="${width} ${height} ${depth}"/> -->
      </geometry>
      <origin rpy="0 0 0" xyz="0 0 0"/>
      <!-- <origin rpy="${origin_rpy}" xyz="${origin_xyz}"/> -->
      <material name="White"/>
    </visual>
    <collision>
      <origin rpy="0 0 0" xyz="0.048263578 -3.1591183e-05 -0.077849126"/>
      <geometry>
        <box size="0.082 0.128 0.3"/>
      </geometry>
    </collision>
  </link>
  <gazebo reference="v1/LeftUpperFoot">
    <material>Gazebo/White</material>
  </gazebo>
  <gazebo reference="v1/LeftUpperFoot">
    <kp>100000.0</kp>
    <kd>1000.0</kd>
    <mu1>1.5</mu1>
    <mu2>1.5</mu2>
    <fdir1>0 0 1</fdir1>
    <maxVel>1.0</maxVel>
    <minDepth>0.00</minDepth>
  </gazebo>

  <joint name="LeftHipRotator" type="revolute">
    <origin rpy="3.14159265359 0 1.57079632679" xyz="0 0.1016 -0.183"/>
    <axis xyz="0 0 1"/>
    <parent link="v1/Pelvis"/>
    <child link="v1/LeftHipRotator"/>
    <limit effort="190" lower="-1.0471975506" upper="0.5235987753" velocity="5.89"/>
    <controller_gains Kd="500" Kp="15000"/>
    <dynamics damping="1.0" friction="0.0"/>
  </joint>
  <gazebo reference="LeftHipRotator">
    <provideFeedback>1</provideFeedback>
  </gazebo>

  <joint name="LeftHipAdductor" type="revolute">
    <origin rpy="1.57079632679 0 0" xyz="0 0 0"/>
    <axis xyz="0 0 1"/>
    <parent link="v1/LeftHipRotator"/>
    <child link="v1/LeftHipAdductor"/>
    <limit effort="350" lower="-0.5235987753" upper="0.26179938765" velocity="7"/>
    <controller_gains Kd="500" Kp="15000"/>
    <dynamics damping="1.0" friction="0.0"/>
  </joint>
  <gazebo reference="LeftHipAdductor">
    <provideFeedback>1</provideFeedback>
  </gazebo>

  <joint name="LeftHipExtensor" type="revolute">
    <origin rpy="1.57079632679 0 1.57079632679" xyz="0 0.061 0"/>
    <axis xyz="0 0 1"/>
    <parent link="v1/LeftHipAdductor"/>
    <child link="v1/LeftLeg"/>
    <limit effort="350" lower="-2.35619448885" upper="1.71042266598" velocity="6.11"/>
    <controller_gains Kd="500" Kp="15000"/>
    <dynamics damping="1.0" friction="0.0"/>
  </joint>
  <gazebo reference="LeftHipExtensor">
    <provideFeedback>1</provideFeedback>
  </gazebo>

  <joint name="LeftKneeExtensor" type="revolute">
    <origin rpy="3.14159265359 0 0" xyz="0.431 0 0.0374"/>
    <axis xyz="0 0 1"/>
    <parent link="v1/LeftLeg"/>
    <child link="v1/LeftShankStructure"/>
    <limit effort="350" lower="-1.90240888359" upper="0.218166156375" velocity="6.11"/>
    <controller_gains Kd="500" Kp="15000"/>
    <dynamics damping="1.0" friction="0.0"/>
  </joint>
  <gazebo reference="LeftKneeExtensor">
    <provideFeedback>1</provideFeedback>
  </gazebo>

  <joint name="LeftAnkleExtensor" type="revolute">
    <origin rpy="3.14159265359 0 0.13" xyz="0.406 0 0"/>
    <axis xyz="0 0 1"/>
    <parent link="v1/LeftShankStructure"/>
    <child link="v1/LeftAnkleYoke"/>
    <limit effort="205" lower="-0.8726646255" upper="0.8726646255" velocity="11"/>
    <controller_gains Kd="400" Kp="15000"/>
    <dynamics damping="1.0" friction="0.0"/>
  </joint>
  <gazebo reference="LeftAnkleExtensor">
    <provideFeedback>1</provideFeedback>
  </gazebo>

  <joint name="LeftAnkle" type="revolute">
    <origin rpy="-1.57079632679 0 0" xyz="0.0127 0 0"/>
    <axis xyz="0 0 1"/>
    <parent link="v1/LeftAnkleYoke"/>
    <child link="v1/LeftUpperFoot"/>
    <limit effort="205" lower="-0.3490658502" upper="0.3490658502" velocity="11"/>
    <controller_gains Kd="400" Kp="15000"/>
    <dynamics damping="1.0" friction="0.0"/>
  </joint>
  <gazebo reference="LeftAnkle">
    <provideFeedback>1</provideFeedback>
  </gazebo>

  <transmission name="LeftHipRotatorTransmission">
    <type>transmission_interface/SimpleTransmission</type>
    <joint name="LeftHipRotator"/>
    <actuator name="/pelvis/lj1">
      <hardwareInterface>EffortJointInterface</hardwareInterface>
      <mechanicalReduction>100</mechanicalReduction>
    </actuator>
    <motorTorqueConstant>0.01</motorTorqueConstant>
  </transmission>

  <transmission name="LeftHipAdductorTransmission">
    <type>transmission_interface/SimpleTransmission</type>
    <joint name="LeftHipAdductor"/>
    <actuator name="/left_leg/j2">
      <hardwareInterface>EffortJointInterface</hardwareInterface>
      <mechanicalReduction>100</mechanicalReduction>
    </actuator>
    <motorTorqueConstant>0.01</motorTorqueConstant>
  </transmission>

  <transmission name="LeftHipExtensorTransmission">
    <type>transmission_interface/SimpleTransmission</type>
    <joint name="LeftHipExtensor"/>
    <actuator name="/left_leg/j3">
      <hardwareInterface>EffortJointInterface</hardwareInterface>
      <mechanicalReduction>100</mechanicalReduction>
    </actuator>
    <motorTorqueConstant>0.01</motorTorqueConstant>
  </transmission>

  <transmission name="LeftKneeExtensorTransmission">
    <type>transmission_interface/SimpleTransmission</type>
    <joint name="LeftKneeExtensor"/>
    <actuator name="/left_leg/j4">
      <hardwareInterface>EffortJointInterface</hardwareInterface>
      <mechanicalReduction>100</mechanicalReduction>
    </actuator>
    <motorTorqueConstant>0.01</motorTorqueConstant>
  </transmission>

  <transmission name="LeftAnkleExtensorTransmission">
    <type>transmission_interface/SimpleTransmission</type>
    <joint name="LeftAnkleExtensor"/>
    <actuator name="/left_leg/j5">
      <hardwareInterface>EffortJointInterface</hardwareInterface>
      <mechanicalReduction>100</mechanicalReduction>
    </actuator>
    <motorTorqueConstant>0.01</motorTorqueConstant>
  </transmission>

  <transmission name="LeftAnkleTransmission">
    <type>transmission_interface/SimpleTransmission</type>
    <joint name="LeftAnkle"/>
    <actuator name="/left_leg/j6">
      <hardwareInterface>EffortJointInterface</hardwareInterface>
      <mechanicalReduction>100</mechanicalReduction>
    </actuator>
    <motorTorqueConstant>0.01</motorTorqueConstant>
  </transmission>
</robot>
