<?xml version="1.0" ?>
<!-- =================================================================================== -->
<!-- |    This document was autogenerated by xacro from xacro/V1_gazebo.xacro          | -->
<!-- |    EDITING THIS FILE BY HAND IS NOT RECOMMENDED                                 | -->
<!-- =================================================================================== -->
<robot name="v1" xmlns:controller="http://playerstage.sourceforge.net/gazebo/xmlschema/#controller" xmlns:interface="http://playerstage.sourceforge.net/gazebo/xmlschema/#interface" xmlns:sensor="http://playerstage.sourceforge.net/gazebo/xmlschema/#sensor" xmlns:xacro="http://www.ros.org/wiki/xacro">

  <link name="v1/Trunk">
    <inertial>
      <mass value="38.3"/>
      <origin rpy="0 0 0" xyz="0.255 0 -0.0981"/>
      <inertia ixx="1.08700825833" ixy="0.0" ixz="0.0" iyy="1.29998179167" iyz="0.0" izz="1.23941991667"/>
    </inertial>
    <visual>
      <geometry>
        <mesh filename="${modelPath}/meshes/2013_05_16/wj3.stl"/>
        <!-- <box size="${width} ${height} ${depth}"/> -->
      </geometry>
      <origin rpy="0 0 0" xyz="0 0 0"/>
      <!-- <origin rpy="${origin_rpy}" xyz="${origin_xyz}"/> -->
      <material name="White"/>
    </visual>
    <collision>
      <geometry>
        <mesh filename="${modelPath}/meshes/2013_05_16/wj3.stl"/>
      </geometry>
      <origin rpy="0 0 0" xyz="0 0 0"/>
    </collision>
  </link>
  <gazebo reference="v1/Trunk">
    <material>Gazebo/White</material>
  </gazebo>

  <link name="v1/LowerNeckExtensor">
    <!-- Virtual Link -->
    <inertial>
      <mass value="0.1"/>
      <origin rpy="0 0 0" xyz="0 0 0"/>
      <inertia ixx="8.33333333333e-05" ixy="0.0" ixz="0.0" iyy="8.33333333333e-05" iyz="0.0" izz="0.000125"/>
    </inertial>
    <visual>
      <origin rpy="0 0 0" xyz="0 0 0"/>
      <geometry>
        <mesh filename="${modelPath}/meshes/2013_05_16/nj1.stl"/>
      </geometry>
      <material name="gold">
        <color rgba="1 0.67 0 1"/>
      </material>
    </visual>
    <collision>
      <origin rpy="0 0 0" xyz="0 0 0"/>
      <geometry>
        <mesh filename="${modelPath}/meshes/2013_05_16/nj1.stl"/>
      </geometry>
    </collision>
  </link>

  <link name="v1/NeckRotator">
    <!-- Virtual Link -->
    <inertial>
      <mass value="0.1"/>
      <origin rpy="0 0 0" xyz="0 0 0"/>
      <inertia ixx="8.33333333333e-05" ixy="0.0" ixz="0.0" iyy="8.33333333333e-05" iyz="0.0" izz="0.000125"/>
    </inertial>
    <visual>
      <origin rpy="0 0 0" xyz="0 0 0"/>
      <geometry>
        <mesh filename="${modelPath}/meshes/2013_05_16/nj2.stl"/>
      </geometry>
      <material name="gold">
        <color rgba="1 0.67 0 1"/>
      </material>
    </visual>
    <collision>
      <origin rpy="0 0 0" xyz="0 0 0"/>
      <geometry>
        <mesh filename="${modelPath}/meshes/2013_05_16/nj2.stl"/>
      </geometry>
    </collision>
  </link>

  <link name="v1/Head">
    <inertial>
      <mass value="3.842"/>
      <origin rpy="0 0 0" xyz="-0.079 0.009 0"/>
      <inertia ixx="0.03012128" ixy="0.0" ixz="0.0" iyy="0.03012128" iyz="0.0" izz="0.03012128"/>
    </inertial>
    <visual>
      <origin rpy="0 0 0" xyz="0 0 0"/>
      <!-- <origin rpy="${origin_rpy}" xyz="${origin_xyz}"/> -->
      <geometry>
        <mesh filename="${modelPath}/meshes/2013_05_16/head.stl"/>
        <!-- <sphere radius="${radius}"/> -->
      </geometry>
      <material name="White"/>
    </visual>
    <collision>
      <origin rpy="0 0 0" xyz="0 0 0"/>
      <geometry>
        <mesh filename="${modelPath}/meshes/2013_05_16/head.stl"/>
      </geometry>
    </collision>
  </link>
  <gazebo reference="v1/Head">
    <material>Gazebo/White</material>
  </gazebo>

  <joint name="LowerNeckExtensor" type="revolute">
    <origin rpy="-1.57079632679 0 0" xyz="0.3383 0 0.0519"/>
    <axis xyz="0 0 1"/>
    <parent link="v1/Trunk"/>
    <child link="v1/LowerNeckExtensor"/>
    <limit effort="26" lower="-1.5707963259" upper="0" velocity="5"/>
    <controller_gains Kd="0" Kp="20000"/>
    <dynamics damping="1.0" friction="0.0"/>
  </joint>
  <gazebo reference="LowerNeckExtensor">
    <provideFeedback>1</provideFeedback>
  </gazebo>

  <joint name="NeckRotator" type="revolute">
    <origin rpy="1.57079632679 0 1.57079632679" xyz="0 0.0519 0"/>
    <axis xyz="0 0 1"/>
    <parent link="v1/LowerNeckExtensor"/>
    <child link="v1/NeckRotator"/>
    <limit effort="26" lower="-1.5707963259" upper="1.5707963259" velocity="5"/>
    <controller_gains Kd="0" Kp="20000"/>
    <dynamics damping="1.0" friction="0.0"/>
  </joint>
  <gazebo reference="NeckRotator">
    <provideFeedback>1</provideFeedback>
  </gazebo>

  <joint name="UpperNeckExtensor" type="revolute">
    <origin rpy="-1.57079632679 0 0" xyz="0.06 0 0.196"/>
    <axis xyz="0 0 1"/>
    <parent link="v1/NeckRotator"/>
    <child link="v1/Head"/>
    <limit effort="26" lower="-0.08726646255" upper="0.78539816295" velocity="5"/>
    <controller_gains Kd="0" Kp="20000"/>
    <dynamics damping="1.0" friction="0.0"/>
  </joint>
  <gazebo reference="UpperNeckExtensor">
    <provideFeedback>1</provideFeedback>
  </gazebo>

  <transmission name="LowerNeckExtensorTransmission">
    <type>transmission_interface/SimpleTransmission</type>
    <joint name="LowerNeckExtensor"/>
    <actuator name="/neck/j1">
      <hardwareInterface>EffortJointInterface</hardwareInterface>
      <mechanicalReduction>100</mechanicalReduction>
    </actuator>
    <motorTorqueConstant>0.01</motorTorqueConstant>
  </transmission>

  <transmission name="NeckRotatorTransmission">
    <type>transmission_interface/SimpleTransmission</type>
    <joint name="NeckRotator"/>
    <actuator name="/neck/j2">
      <hardwareInterface>EffortJointInterface</hardwareInterface>
      <mechanicalReduction>100</mechanicalReduction>
    </actuator>
    <motorTorqueConstant>0.01</motorTorqueConstant>
  </transmission>

  <transmission name="UpperNeckExtensorTransmission">
    <type>transmission_interface/SimpleTransmission</type>
    <joint name="UpperNeckExtensor"/>
    <actuator name="/neck/j3">
      <hardwareInterface>EffortJointInterface</hardwareInterface>
      <mechanicalReduction>100</mechanicalReduction>
    </actuator>
    <motorTorqueConstant>0.01</motorTorqueConstant>
  </transmission>

  <link name="v1/RightShoulderExtensor">
    <inertial>
      <mass value="2.45"/>
      <origin rpy="0 0 0" xyz="0 -0.01204 -0.251"/>
      <inertia ixx="0.0126828333333" ixy="0.0" ixz="0.0" iyy="0.00971016666667" iyz="0.0" izz="0.0136889666667"/>
    </inertial>
    <visual>
      <geometry>
        <mesh filename="${modelPath}/meshes/2013_05_16/aj1_Right.stl"/>
        <!-- <box size="${width} ${height} ${depth}"/> -->
      </geometry>
      <origin rpy="0 0 0" xyz="0 0 0"/>
      <!-- <origin rpy="${origin_rpy}" xyz="${origin_xyz}"/> -->
      <material name="Gold"/>
    </visual>
    <collision>
      <geometry>
        <mesh filename="${modelPath}/meshes/2013_05_16/aj1_Right.stl"/>
      </geometry>
      <origin rpy="0 0 0" xyz="0 0 0"/>
    </collision>
  </link>
  <gazebo reference="v1/RightShoulderExtensor">
    <material>Gazebo/Gold</material>
  </gazebo>

  <link name="v1/RightShoulderAdductor">
    <inertial>
      <mass value="3.67"/>
      <origin rpy="0 0 0" xyz="0.044 -0.0034 0"/>
      <inertia ixx="0.0115718158333" ixy="0.0" ixz="0.0" iyy="0.0166486491667" iyz="0.0" izz="0.0172373783333"/>
    </inertial>
    <visual>
      <geometry>
        <mesh filename="${modelPath}/meshes/2013_05_16/aj2.stl"/>
        <!-- <box size="${width} ${height} ${depth}"/> -->
      </geometry>
      <origin rpy="0 0 0" xyz="0 0 0"/>
      <!-- <origin rpy="${origin_rpy}" xyz="${origin_xyz}"/> -->
      <material name="White"/>
    </visual>
    <collision>
      <geometry>
        <mesh filename="${modelPath}/meshes/2013_05_16/aj2.stl"/>
      </geometry>
      <origin rpy="0 0 0" xyz="0 0 0"/>
    </collision>
  </link>
  <gazebo reference="v1/RightShoulderAdductor">
    <material>Gazebo/White</material>
  </gazebo>

  <link name="v1/RightShoulderRotator">
    <inertial>
      <mass value="2.575"/>
      <origin rpy="0 0 0" xyz="0 0.006 -0.236"/>
      <inertia ixx="0.0227863895833" ixy="0.0" ixz="0.0" iyy="0.0213984645833" iyz="0.0" izz="0.00932579166667"/>
    </inertial>
    <visual>
      <geometry>
        <mesh filename="${modelPath}/meshes/2013_05_16/aj3_Right.stl"/>
        <!-- <box size="${width} ${height} ${depth}"/> -->
      </geometry>
      <origin rpy="0 0 0" xyz="0 0 0"/>
      <!-- <origin rpy="${origin_rpy}" xyz="${origin_xyz}"/> -->
      <material name="White"/>
    </visual>
    <collision>
      <geometry>
        <mesh filename="${modelPath}/meshes/2013_05_16/aj3_Right.stl"/>
      </geometry>
      <origin rpy="0 0 0" xyz="0 0 0"/>
    </collision>
  </link>
  <gazebo reference="v1/RightShoulderRotator">
    <material>Gazebo/White</material>
  </gazebo>

  <link name="v1/RightElbowExtensor">
    <inertial>
      <mass value="1.367"/>
      <origin rpy="0 0 0" xyz="0.0270 0.0302 0"/>
      <inertia ixx="0.004941705" ixy="0.0" ixz="0.0" iyy="0.00469849291667" iyz="0.0" izz="0.00530133991667"/>
    </inertial>
    <visual>
      <geometry>
        <mesh filename="${modelPath}/meshes/2013_05_16/aj4.stl"/>
        <!-- <box size="${width} ${height} ${depth}"/> -->
      </geometry>
      <origin rpy="0 0 0" xyz="0 0 0"/>
      <!-- <origin rpy="${origin_rpy}" xyz="${origin_xyz}"/> -->
      <material name="Gold"/>
    </visual>
    <collision>
      <geometry>
        <mesh filename="${modelPath}/meshes/2013_05_16/aj4.stl"/>
      </geometry>
      <origin rpy="0 0 0" xyz="0 0 0"/>
    </collision>
  </link>
  <gazebo reference="v1/RightElbowExtensor">
    <material>Gazebo/Gold</material>
  </gazebo>

  <joint name="RightShoulderExtensor" type="revolute">
    <origin rpy="1.57079632679 0 0" xyz="0.29842 0 -0.03157"/>
    <axis xyz="0 0 1"/>
    <parent link="v1/Trunk"/>
    <child link="v1/RightShoulderExtensor"/>
    <limit effort="190" lower="-3.1415926518" upper="3.1415926518" velocity="5.89"/>
    <controller_gains Kd="400" Kp="20000"/>
    <dynamics damping="1.0" friction="0.0"/>
  </joint>
  <gazebo reference="RightShoulderExtensor">
    <provideFeedback>1</provideFeedback>
  </gazebo>

  <joint name="RightShoulderAdductor" type="revolute">
    <origin rpy="1.57079632679 0 3.14159265359" xyz="0 0 -0.246"/>
    <axis xyz="0 0 1"/>
    <parent link="v1/RightShoulderExtensor"/>
    <child link="v1/RightShoulderAdductor"/>
    <limit effort="190" lower="-3.05432618925" upper="-0.1745329251" velocity="5.89"/>
    <controller_gains Kd="400" Kp="20000"/>
    <dynamics damping="1.0" friction="0.0"/>
  </joint>
  <gazebo reference="RightShoulderAdductor">
    <provideFeedback>1</provideFeedback>
  </gazebo>

  <joint name="RightShoulderSupinator" type="revolute">
    <origin rpy="-1.57079632679 0 1.57079632679" xyz="0 0 0"/>
    <axis xyz="0 0 1"/>
    <parent link="v1/RightShoulderAdductor"/>
    <child link="v1/RightShoulderRotator"/>
    <limit effort="65" lower="-1.5707963259" upper="1.5707963259" velocity="11.5"/>
    <controller_gains Kd="400" Kp="20000"/>
    <dynamics damping="1.0" friction="0.0"/>
  </joint>
  <gazebo reference="RightShoulderSupinator">
    <provideFeedback>1</provideFeedback>
  </gazebo>

  <joint name="RightElbowExtensor" type="revolute">
    <origin rpy="1.57079632679 0 1.57079632679" xyz="0 -0.0254 -0.33"/>
    <axis xyz="0 0 1"/>
    <parent link="v1/RightShoulderRotator"/>
    <child link="v1/RightElbowExtensor"/>
    <limit effort="65" lower="-1.9198621761" upper="-0.08726646255" velocity="11.5"/>
    <controller_gains Kd="400" Kp="20000"/>
    <dynamics damping="1.0" friction="0.0"/>
  </joint>
  <gazebo reference="RightElbowExtensor">
    <provideFeedback>1</provideFeedback>
  </gazebo>

  <link name="v1/RightForearm">
    <inertial>
      <mass value="2.703"/>
      <origin rpy="0 0 0" xyz="0 0.0006 -0.12"/>
      <inertia ixx="0.01633175125" ixy="0.0" ixz="0.0" iyy="0.0169338445" iyz="0.0" izz="0.00666402125"/>
    </inertial>
    <visual>
      <geometry>
        <mesh filename="${modelPath}/meshes/2013_05_16/aj5_Right.stl"/>
        <!-- <box size="${width} ${height} ${depth}"/> -->
      </geometry>
      <origin rpy="0 0 0" xyz="0 0 0"/>
      <!-- <origin rpy="${origin_rpy}" xyz="${origin_xyz}"/> -->
      <material name="White"/>
    </visual>
    <collision>
      <geometry>
        <mesh filename="${modelPath}/meshes/2013_05_16/aj5_Right.stl"/>
      </geometry>
      <origin rpy="0 0 0" xyz="0 0 0"/>
    </collision>
  </link>
  <gazebo reference="v1/RightForearm">
    <material>Gazebo/White</material>
  </gazebo>

  <link name="v1/RightWristYoke">
    <inertial>
      <mass value="0.1"/>
      <origin rpy="0 0 0" xyz="0 0 0"/>
      <inertia ixx="2.25083333333e-05" ixy="0.0" ixz="0.0" iyy="2.9175e-05" iyz="0.0" izz="8.33333333333e-06"/>
    </inertial>
    <visual>
      <geometry>
        <box size="0.03 0.01 0.051"/>
      </geometry>
      <origin rpy="0 0 0" xyz="0 0 0"/>
      <material name="Gray"/>
    </visual>
    <collision>
      <geometry>
        <box size="0.03 0.01 0.051"/>
      </geometry>
      <origin rpy="0 0 0" xyz="0 0 0"/>
    </collision>
  </link>

  <link name="v1/RightPalm">
    <inertial>
      <mass value="0.712"/>
      <origin rpy="0 0 0" xyz="0.0425 0 0"/>
      <inertia ixx="0.000679010666667" ixy="0.0" ixz="0.0" iyy="0.000514360666667" iyz="0.0" izz="0.00102201666667"/>
    </inertial>
    <visual>
      <geometry>
        <mesh filename="${modelPath}/meshes/2013_05_16/palm_Right.stl"/>
        <!-- <box size="${width} ${height} ${depth}"/> -->
      </geometry>
      <origin rpy="0 0 0" xyz="0 0 0"/>
      <!-- <origin rpy="${origin_rpy}" xyz="${origin_xyz}"/> -->
      <material name="Gold"/>
    </visual>
    <collision>
      <geometry>
        <mesh filename="${modelPath}/meshes/2013_05_16/palm_Right.stl"/>
      </geometry>
      <origin rpy="0 0 0" xyz="0 0 0"/>
    </collision>
  </link>
  <gazebo reference="v1/RightPalm">
    <material>Gazebo/Gold</material>
  </gazebo>

  <joint name="RightForearmSupinator" type="revolute">
    <origin rpy="1.57079632679 0 3.14159265359" xyz="0.0254 0 0"/>
    <axis xyz="0 0 1"/>
    <parent link="v1/RightElbowExtensor"/>
    <child link="v1/RightForearm"/>
    <limit effort="26" lower="-2.35619448885" upper="2.35619448885" velocity="5"/>
    <controller_gains Kd="0" Kp="20000"/>
    <dynamics damping="1.0" friction="0.0"/>
  </joint>
  <gazebo reference="RightForearmSupinator">
    <provideFeedback>1</provideFeedback>
  </gazebo>

  <joint name="RightWristExtensor" type="revolute">
    <origin rpy="-1.57079632679 0 1.57079632679" xyz="0 0 -0.287"/>
    <axis xyz="0 0 1"/>
    <parent link="v1/RightForearm"/>
    <child link="v1/RightWristYoke"/>
    <limit effort="14" lower="-0.8726646255" upper="0.6981317004" velocity="1"/>
    <controller_gains Kd="400" Kp="20000"/>
    <dynamics damping="1.0" friction="0.0"/>
  </joint>
  <gazebo reference="RightWristExtensor">
    <provideFeedback>1</provideFeedback>
  </gazebo>

  <joint name="RightWrist" type="revolute">
    <origin rpy="1.57079632679 0 1.57079632679" xyz="0 0 0"/>
    <axis xyz="0 0 1"/>
    <parent link="v1/RightWristYoke"/>
    <child link="v1/RightPalm"/>
    <limit effort="14" lower="-0.5235987753" upper="0.43633231275" velocity="1"/>
    <controller_gains Kd="400" Kp="20000"/>
    <dynamics damping="1.0" friction="0.0"/>
  </joint>
  <gazebo reference="RightWrist">
    <provideFeedback>1</provideFeedback>
  </gazebo>

  <transmission name="RightShoulderExtensorTransmission">
    <type>transmission_interface/SimpleTransmission</type>
    <joint name="RightShoulderExtensor"/>
    <actuator name="/trunk/raj1">
      <hardwareInterface>EffortJointInterface</hardwareInterface>
      <mechanicalReduction>100</mechanicalReduction>
    </actuator>
    <motorTorqueConstant>0.01</motorTorqueConstant>
  </transmission>

  <transmission name="RightShoulderAdductorTransmission">
    <type>transmission_interface/SimpleTransmission</type>
    <joint name="RightShoulderAdductor"/>
    <actuator name="/right_arm/j2">
      <hardwareInterface>EffortJointInterface</hardwareInterface>
      <mechanicalReduction>100</mechanicalReduction>
    </actuator>
    <motorTorqueConstant>0.01</motorTorqueConstant>
  </transmission>

  <transmission name="RightShoulderSupinatorTransmission">
    <type>transmission_interface/SimpleTransmission</type>
    <joint name="RightShoulderSupinator"/>
    <actuator name="/right_arm/j3">
      <hardwareInterface>EffortJointInterface</hardwareInterface>
      <mechanicalReduction>100</mechanicalReduction>
    </actuator>
    <motorTorqueConstant>0.01</motorTorqueConstant>
  </transmission>

  <transmission name="RightElbowExtensorTransmission">
    <type>transmission_interface/SimpleTransmission</type>
    <joint name="RightElbowExtensor"/>
    <actuator name="/right_arm/j4">
      <hardwareInterface>EffortJointInterface</hardwareInterface>
      <mechanicalReduction>100</mechanicalReduction>
    </actuator>
    <motorTorqueConstant>0.01</motorTorqueConstant>
  </transmission>

  <transmission name="RightForearmSupinatorTransmission">
    <type>transmission_interface/SimpleTransmission</type>
    <joint name="RightForearmSupinator"/>
    <actuator name="/right_arm/j5">
      <hardwareInterface>EffortJointInterface</hardwareInterface>
      <mechanicalReduction>1</mechanicalReduction>
    </actuator>
    <motorTorqueConstant>0</motorTorqueConstant>
  </transmission>

  <transmission name="RightWristExtensorTransmission">
    <type>transmission_interface/SimpleTransmission</type>
    <joint name="RightWristExtensor"/>
    <actuator name="/right_arm/forearm_driver1/wrist_right">
      <hardwareInterface>EffortJointInterface</hardwareInterface>
      <mechanicalReduction>1</mechanicalReduction>
    </actuator>
    <motorTorqueConstant>0</motorTorqueConstant>
  </transmission>

  <transmission name="RightWristTransmission">
    <type>transmission_interface/SimpleTransmission</type>
    <joint name="RightWrist"/>
    <actuator name="/right_arm/forearm_driver1/wrist_left">
      <hardwareInterface>EffortJointInterface</hardwareInterface>
      <mechanicalReduction>1</mechanicalReduction>
    </actuator>
    <motorTorqueConstant>0</motorTorqueConstant>
  </transmission>

  <link name="v1/LeftShoulderExtensor">
    <inertial>
      <mass value="2.45"/>
      <origin rpy="0 0 0" xyz="0 -0.01204 0.251"/>
      <inertia ixx="0.0126828333333" ixy="0.0" ixz="0.0" iyy="0.00971016666667" iyz="0.0" izz="0.0136889666667"/>
    </inertial>
    <visual>
      <geometry>
        <mesh filename="${modelPath}/meshes/2013_05_16/aj1_Left.stl"/>
        <!-- <box size="${width} ${height} ${depth}"/> -->
      </geometry>
      <origin rpy="0 0 0" xyz="0 0 0"/>
      <!-- <origin rpy="${origin_rpy}" xyz="${origin_xyz}"/> -->
      <material name="Gold"/>
    </visual>
    <collision>
      <geometry>
        <mesh filename="${modelPath}/meshes/2013_05_16/aj1_Left.stl"/>
      </geometry>
      <origin rpy="0 0 0" xyz="0 0 0"/>
    </collision>
  </link>
  <gazebo reference="v1/LeftShoulderExtensor">
    <material>Gazebo/Gold</material>
  </gazebo>

  <link name="v1/LeftShoulderAdductor">
    <inertial>
      <mass value="3.67"/>
      <origin rpy="0 0 0" xyz="0.044 -0.0034 0"/>
      <inertia ixx="0.0115718158333" ixy="0.0" ixz="0.0" iyy="0.0166486491667" iyz="0.0" izz="0.0172373783333"/>
    </inertial>
    <visual>
      <geometry>
        <mesh filename="${modelPath}/meshes/2013_05_16/aj2.stl"/>
        <!-- <box size="${width} ${height} ${depth}"/> -->
      </geometry>
      <origin rpy="0 0 0" xyz="0 0 0"/>
      <!-- <origin rpy="${origin_rpy}" xyz="${origin_xyz}"/> -->
      <material name="White"/>
    </visual>
    <collision>
      <geometry>
        <mesh filename="${modelPath}/meshes/2013_05_16/aj2.stl"/>
      </geometry>
      <origin rpy="0 0 0" xyz="0 0 0"/>
    </collision>
  </link>
  <gazebo reference="v1/LeftShoulderAdductor">
    <material>Gazebo/White</material>
  </gazebo>

  <link name="v1/LeftShoulderRotator">
    <inertial>
      <mass value="2.575"/>
      <origin rpy="0 0 0" xyz="0 -0.006 0.236"/>
      <inertia ixx="0.0227863895833" ixy="0.0" ixz="0.0" iyy="0.0213984645833" iyz="0.0" izz="0.00932579166667"/>
    </inertial>
    <visual>
      <geometry>
        <mesh filename="${modelPath}/meshes/2013_05_16/aj3_Left.stl"/>
        <!-- <box size="${width} ${height} ${depth}"/> -->
      </geometry>
      <origin rpy="0 0 0" xyz="0 0 0"/>
      <!-- <origin rpy="${origin_rpy}" xyz="${origin_xyz}"/> -->
      <material name="White"/>
    </visual>
    <collision>
      <geometry>
        <mesh filename="${modelPath}/meshes/2013_05_16/aj3_Left.stl"/>
      </geometry>
      <origin rpy="0 0 0" xyz="0 0 0"/>
    </collision>
  </link>
  <gazebo reference="v1/LeftShoulderRotator">
    <material>Gazebo/White</material>
  </gazebo>

  <link name="v1/LeftElbowExtensor">
    <inertial>
      <mass value="1.367"/>
      <origin rpy="0 0 0" xyz="0.0270 0.0302 0"/>
      <inertia ixx="0.004941705" ixy="0.0" ixz="0.0" iyy="0.00469849291667" iyz="0.0" izz="0.00530133991667"/>
    </inertial>
    <visual>
      <geometry>
        <mesh filename="${modelPath}/meshes/2013_05_16/aj4.stl"/>
        <!-- <box size="${width} ${height} ${depth}"/> -->
      </geometry>
      <origin rpy="0 0 0" xyz="0 0 0"/>
      <!-- <origin rpy="${origin_rpy}" xyz="${origin_xyz}"/> -->
      <material name="Gold"/>
    </visual>
    <collision>
      <geometry>
        <mesh filename="${modelPath}/meshes/2013_05_16/aj4.stl"/>
      </geometry>
      <origin rpy="0 0 0" xyz="0 0 0"/>
    </collision>
  </link>
  <gazebo reference="v1/LeftElbowExtensor">
    <material>Gazebo/Gold</material>
  </gazebo>

  <joint name="LeftShoulderExtensor" type="revolute">
    <origin rpy="1.57079632679 0 0" xyz="0.29842 0 -0.03157"/>
    <axis xyz="0 0 1"/>
    <parent link="v1/Trunk"/>
    <child link="v1/LeftShoulderExtensor"/>
    <limit effort="190" lower="-3.1415926518" upper="3.1415926518" velocity="5.89"/>
    <controller_gains Kd="400" Kp="20000"/>
    <dynamics damping="1.0" friction="0.0"/>
  </joint>
  <gazebo reference="LeftShoulderExtensor">
    <provideFeedback>1</provideFeedback>
  </gazebo>

  <joint name="LeftShoulderAdductor" type="revolute">
    <origin rpy="-1.57079632679 0 3.14159265359" xyz="0 0 0.246"/>
    <axis xyz="0 0 1"/>
    <parent link="v1/LeftShoulderExtensor"/>
    <child link="v1/LeftShoulderAdductor"/>
    <limit effort="190" lower="-3.05432618925" upper="-0.1745329251" velocity="5.89"/>
    <controller_gains Kd="400" Kp="20000"/>
    <dynamics damping="1.0" friction="0.0"/>
  </joint>
  <gazebo reference="LeftShoulderAdductor">
    <provideFeedback>1</provideFeedback>
  </gazebo>

  <joint name="LeftShoulderSupinator" type="revolute">
    <origin rpy="-1.57079632679 0 -1.57079632679" xyz="0 0 0"/>
    <axis xyz="0 0 1"/>
    <parent link="v1/LeftShoulderAdductor"/>
    <child link="v1/LeftShoulderRotator"/>
    <limit effort="65" lower="-1.5707963259" upper="1.5707963259" velocity="11.5"/>
    <controller_gains Kd="400" Kp="20000"/>
    <dynamics damping="1.0" friction="0.0"/>
  </joint>
  <gazebo reference="LeftShoulderSupinator">
    <provideFeedback>1</provideFeedback>
  </gazebo>

  <joint name="LeftElbowExtensor" type="revolute">
    <origin rpy="-1.57079632679 0 -1.57079632679" xyz="0 0.0254 0.33"/>
    <axis xyz="0 0 1"/>
    <parent link="v1/LeftShoulderRotator"/>
    <child link="v1/LeftElbowExtensor"/>
    <limit effort="65" lower="-1.9198621761" upper="-0.08726646255" velocity="11.5"/>
    <controller_gains Kd="400" Kp="20000"/>
    <dynamics damping="1.0" friction="0.0"/>
  </joint>
  <gazebo reference="LeftElbowExtensor">
    <provideFeedback>1</provideFeedback>
  </gazebo>

  <link name="v1/LeftForearm">
    <inertial>
      <mass value="2.703"/>
      <origin rpy="0 0 0" xyz="0 -0.0006 0.12"/>
      <inertia ixx="0.01633175125" ixy="0.0" ixz="0.0" iyy="0.0169338445" iyz="0.0" izz="0.00666402125"/>
    </inertial>
    <visual>
      <geometry>
        <mesh filename="${modelPath}/meshes/2013_05_16/aj5_Left.stl"/>
        <!-- <box size="${width} ${height} ${depth}"/> -->
      </geometry>
      <origin rpy="0 0 0" xyz="0 0 0"/>
      <!-- <origin rpy="${origin_rpy}" xyz="${origin_xyz}"/> -->
      <material name="White"/>
    </visual>
    <collision>
      <geometry>
        <mesh filename="${modelPath}/meshes/2013_05_16/aj5_Left.stl"/>
      </geometry>
      <origin rpy="0 0 0" xyz="0 0 0"/>
    </collision>
  </link>
  <gazebo reference="v1/LeftForearm">
    <material>Gazebo/White</material>
  </gazebo>

  <link name="v1/LeftWristYoke">
    <inertial>
      <mass value="0.1"/>
      <origin rpy="0 0 0" xyz="0 0 0"/>
      <inertia ixx="2.25083333333e-05" ixy="0.0" ixz="0.0" iyy="2.9175e-05" iyz="0.0" izz="8.33333333333e-06"/>
    </inertial>
    <visual>
      <geometry>
        <box size="0.03 0.01 0.051"/>
      </geometry>
      <origin rpy="0 0 0" xyz="0 0 0"/>
      <material name="Gray"/>
    </visual>
    <collision>
      <geometry>
        <box size="0.03 0.01 0.051"/>
      </geometry>
      <origin rpy="0 0 0" xyz="0 0 0"/>
    </collision>
  </link>

  <link name="v1/LeftPalm">
    <inertial>
      <mass value="0.712"/>
      <origin rpy="0 0 0" xyz="0.0425 0 0"/>
      <inertia ixx="0.000679010666667" ixy="0.0" ixz="0.0" iyy="0.000514360666667" iyz="0.0" izz="0.00102201666667"/>
    </inertial>
    <visual>
      <geometry>
        <mesh filename="${modelPath}/meshes/2013_05_16/palm_Left.stl"/>
        <!-- <box size="${width} ${height} ${depth}"/> -->
      </geometry>
      <origin rpy="0 0 0" xyz="0 0 0"/>
      <!-- <origin rpy="${origin_rpy}" xyz="${origin_xyz}"/> -->
      <material name="Gold"/>
    </visual>
    <collision>
      <geometry>
        <mesh filename="${modelPath}/meshes/2013_05_16/palm_Left.stl"/>
      </geometry>
      <origin rpy="0 0 0" xyz="0 0 0"/>
    </collision>
  </link>
  <gazebo reference="v1/LeftPalm">
    <material>Gazebo/Gold</material>
  </gazebo>

  <joint name="LeftForearmSupinator" type="revolute">
    <origin rpy="-1.57079632679 0 3.14159265359" xyz="0.0254 0 0"/>
    <axis xyz="0 0 1"/>
    <parent link="v1/LeftElbowExtensor"/>
    <child link="v1/LeftForearm"/>
    <limit effort="26" lower="-2.35619448885" upper="2.35619448885" velocity="5"/>
    <controller_gains Kd="0" Kp="20000"/>
    <dynamics damping="1.0" friction="0.0"/>
  </joint>
  <gazebo reference="LeftForearmSupinator">
    <provideFeedback>1</provideFeedback>
  </gazebo>

  <joint name="LeftWristExtensor" type="revolute">
    <origin rpy="-1.57079632679 0 -1.57079632679" xyz="0 0 0.287"/>
    <axis xyz="0 0 1"/>
    <parent link="v1/LeftForearm"/>
    <child link="v1/LeftWristYoke"/>
    <limit effort="14" lower="-0.8726646255" upper="0.6981317004" velocity="1"/>
    <controller_gains Kd="400" Kp="20000"/>
    <dynamics damping="1.0" friction="0.0"/>
  </joint>
  <gazebo reference="LeftWristExtensor">
    <provideFeedback>1</provideFeedback>
  </gazebo>

  <joint name="LeftWrist" type="revolute">
    <origin rpy="-1.57079632679 0 -1.57079632679" xyz="0 0 0"/>
    <axis xyz="0 0 1"/>
    <parent link="v1/LeftWristYoke"/>
    <child link="v1/LeftPalm"/>
    <limit effort="14" lower="-0.5235987753" upper="0.43633231275" velocity="1"/>
    <controller_gains Kd="400" Kp="20000"/>
    <dynamics damping="1.0" friction="0.0"/>
  </joint>
  <gazebo reference="LeftWrist">
    <provideFeedback>1</provideFeedback>
  </gazebo>

  <transmission name="LeftShoulderExtensorTransmission">
    <type>transmission_interface/SimpleTransmission</type>
    <joint name="LeftShoulderExtensor"/>
    <actuator name="/trunk/laj1">
      <hardwareInterface>EffortJointInterface</hardwareInterface>
      <mechanicalReduction>100</mechanicalReduction>
    </actuator>
    <motorTorqueConstant>0.01</motorTorqueConstant>
  </transmission>

  <transmission name="LeftShoulderAdductorTransmission">
    <type>transmission_interface/SimpleTransmission</type>
    <joint name="LeftShoulderAdductor"/>
    <actuator name="/left_arm/j2">
      <hardwareInterface>EffortJointInterface</hardwareInterface>
      <mechanicalReduction>100</mechanicalReduction>
    </actuator>
    <motorTorqueConstant>0.01</motorTorqueConstant>
  </transmission>

  <transmission name="LeftShoulderSupinatorTransmission">
    <type>transmission_interface/SimpleTransmission</type>
    <joint name="LeftShoulderSupinator"/>
    <actuator name="/left_arm/j3">
      <hardwareInterface>EffortJointInterface</hardwareInterface>
      <mechanicalReduction>100</mechanicalReduction>
    </actuator>
    <motorTorqueConstant>0.01</motorTorqueConstant>
  </transmission>

  <transmission name="LeftElbowExtensorTransmission">
    <type>transmission_interface/SimpleTransmission</type>
    <joint name="LeftElbowExtensor"/>
    <actuator name="/left_arm/j4">
      <hardwareInterface>EffortJointInterface</hardwareInterface>
      <mechanicalReduction>100</mechanicalReduction>
    </actuator>
    <motorTorqueConstant>0.01</motorTorqueConstant>
  </transmission>

  <transmission name="LeftForearmSupinatorTransmission">
    <type>transmission_interface/SimpleTransmission</type>
    <joint name="LeftForearmSupinator"/>
    <actuator name="/left_arm/j5">
      <hardwareInterface>EffortJointInterface</hardwareInterface>
      <mechanicalReduction>1</mechanicalReduction>
    </actuator>

    <motorTorqueConstant>0</motorTorqueConstant>
  </transmission>
  <transmission name="LeftWristExtensorTransmission">
    <type>transmission_interface/SimpleTransmission</type>
    <joint name="LeftWristExtensor"/>
    <actuator name="/left_arm/forearm_driver1/wrist_left">
      <hardwareInterface>EffortJointInterface</hardwareInterface>
      <mechanicalReduction>1</mechanicalReduction>
    </actuator>
    <motorTorqueConstant>0</motorTorqueConstant>
  </transmission>

  <transmission name="LeftWristTransmission">
    <type>transmission_interface/SimpleTransmission</type>
    <joint name="LeftWrist"/>
    <actuator name="/left_arm/forearm_driver1/wrist_right">
      <hardwareInterface>EffortJointInterface</hardwareInterface>
      <mechanicalReduction>1</mechanicalReduction>
    </actuator>
    <motorTorqueConstant>0</motorTorqueConstant>
  </transmission>
</robot>
